[2025-04-09 08:37:32 +0800] [1547] [INFO] Starting gunicorn 23.0.0
[2025-04-09 08:37:32 +0800] [1547] [INFO] Listening at: http://127.0.0.1:8000 (1547)
[2025-04-09 08:37:32 +0800] [1547] [INFO] Using worker: sync
[2025-04-09 08:37:32 +0800] [1548] [INFO] Booting worker with pid: 1548
[2025-04-09 08:37:32 +0800] [1549] [INFO] Booting worker with pid: 1549
[2025-04-09 08:37:32 +0800] [1550] [INFO] Booting worker with pid: 1550
[2025-04-09 08:37:32 +0800] [1551] [INFO] Booting worker with pid: 1551
[2025-04-09 08:37:32 +0800] [1552] [INFO] Booting worker with pid: 1552
[2025-04-09 08:37:32 +0800] [1553] [INFO] Booting worker with pid: 1553
[2025-04-09 08:37:32 +0800] [1554] [INFO] Booting worker with pid: 1554
[2025-04-09 08:37:32 +0800] [1555] [INFO] Booting worker with pid: 1555
[2025-04-09 08:37:32 +0800] [1556] [INFO] Booting worker with pid: 1556
[2025-04-09 08:37:33 +0800] [1557] [INFO] Booting worker with pid: 1557
[2025-04-09 08:37:33 +0800] [1558] [INFO] Booting worker with pid: 1558
[2025-04-09 08:37:33 +0800] [1559] [INFO] Booting worker with pid: 1559
[2025-04-09 08:37:33 +0800] [1560] [INFO] Booting worker with pid: 1560
[2025-04-09 08:37:33 +0800] [1561] [INFO] Booting worker with pid: 1561
[2025-04-09 08:37:33 +0800] [1562] [INFO] Booting worker with pid: 1562
[2025-04-09 08:37:33 +0800] [1563] [INFO] Booting worker with pid: 1563
[2025-04-09 08:37:33 +0800] [1564] [INFO] Booting worker with pid: 1564
[2025-04-09 08:38:18 +0800] [1560] [ERROR] Exception in worker process
Traceback (most recent call last):
  File "/mnt/c/Users/HAng3/Documents/wafer-defect-library/backend/venv/lib/python3.12/site-packages/gunicorn/arbiter.py", line 608, in spawn_worker
    worker.init_process()
  File "/mnt/c/Users/HAng3/Documents/wafer-defect-library/backend/venv/lib/python3.12/site-packages/gunicorn/workers/base.py", line 135, in init_process
    self.load_wsgi()
  File "/mnt/c/Users/HAng3/Documents/wafer-defect-library/backend/venv/lib/python3.12/site-packages/gunicorn/workers/base.py", line 147, in load_wsgi
    self.wsgi = self.app.wsgi()
                ^^^^^^^^^^^^^^^
  File "/mnt/c/Users/HAng3/Documents/wafer-defect-library/backend/venv/lib/python3.12/site-packages/gunicorn/app/base.py", line 66, in wsgi
    self.callable = self.load()
                    ^^^^^^^^^^^
  File "/mnt/c/Users/HAng3/Documents/wafer-defect-library/backend/venv/lib/python3.12/site-packages/gunicorn/app/wsgiapp.py", line 57, in load
    return self.load_wsgiapp()
           ^^^^^^^^^^^^^^^^^^^
  File "/mnt/c/Users/HAng3/Documents/wafer-defect-library/backend/venv/lib/python3.12/site-packages/gunicorn/app/wsgiapp.py", line 47, in load_wsgiapp
    return util.import_app(self.app_uri)
           ^^^^^^^^^^^^^^^^^^^^^^^^^^^^^
  File "/mnt/c/Users/HAng3/Documents/wafer-defect-library/backend/venv/lib/python3.12/site-packages/gunicorn/util.py", line 370, in import_app
    mod = importlib.import_module(module)
          ^^^^^^^^^^^^^^^^^^^^^^^^^^^^^^^
  File "/usr/lib/python3.12/importlib/__init__.py", line 90, in import_module
    return _bootstrap._gcd_import(name[level:], package, level)
           ^^^^^^^^^^^^^^^^^^^^^^^^^^^^^^^^^^^^^^^^^^^^^^^^^^^^
  File "<frozen importlib._bootstrap>", line 1387, in _gcd_import
  File "<frozen importlib._bootstrap>", line 1360, in _find_and_load
  File "<frozen importlib._bootstrap>", line 1331, in _find_and_load_unlocked
  File "<frozen importlib._bootstrap>", line 935, in _load_unlocked
  File "<frozen importlib._bootstrap_external>", line 995, in exec_module
  File "<frozen importlib._bootstrap>", line 488, in _call_with_frames_removed
  File "/mnt/c/Users/HAng3/Documents/wafer-defect-library/backend/app.py", line 5, in <module>
    from flask_cors import CORS
ModuleNotFoundError: No module named 'flask_cors'
[2025-04-09 08:38:18 +0800] [1549] [ERROR] Exception in worker process
Traceback (most recent call last):
  File "/mnt/c/Users/HAng3/Documents/wafer-defect-library/backend/venv/lib/python3.12/site-packages/gunicorn/arbiter.py", line 608, in spawn_worker
    worker.init_process()
  File "/mnt/c/Users/HAng3/Documents/wafer-defect-library/backend/venv/lib/python3.12/site-packages/gunicorn/workers/base.py", line 135, in init_process
    self.load_wsgi()
  File "/mnt/c/Users/HAng3/Documents/wafer-defect-library/backend/venv/lib/python3.12/site-packages/gunicorn/workers/base.py", line 147, in load_wsgi
    self.wsgi = self.app.wsgi()
                ^^^^^^^^^^^^^^^
  File "/mnt/c/Users/HAng3/Documents/wafer-defect-library/backend/venv/lib/python3.12/site-packages/gunicorn/app/base.py", line 66, in wsgi
    self.callable = self.load()
                    ^^^^^^^^^^^
  File "/mnt/c/Users/HAng3/Documents/wafer-defect-library/backend/venv/lib/python3.12/site-packages/gunicorn/app/wsgiapp.py", line 57, in load
    return self.load_wsgiapp()
           ^^^^^^^^^^^^^^^^^^^
  File "/mnt/c/Users/HAng3/Documents/wafer-defect-library/backend/venv/lib/python3.12/site-packages/gunicorn/app/wsgiapp.py", line 47, in load_wsgiapp
    return util.import_app(self.app_uri)
           ^^^^^^^^^^^^^^^^^^^^^^^^^^^^^
  File "/mnt/c/Users/HAng3/Documents/wafer-defect-library/backend/venv/lib/python3.12/site-packages/gunicorn/util.py", line 370, in import_app
    mod = importlib.import_module(module)
          ^^^^^^^^^^^^^^^^^^^^^^^^^^^^^^^
  File "/usr/lib/python3.12/importlib/__init__.py", line 90, in import_module
    return _bootstrap._gcd_import(name[level:], package, level)
           ^^^^^^^^^^^^^^^^^^^^^^^^^^^^^^^^^^^^^^^^^^^^^^^^^^^^
  File "<frozen importlib._bootstrap>", line 1387, in _gcd_import
  File "<frozen importlib._bootstrap>", line 1360, in _find_and_load
  File "<frozen importlib._bootstrap>", line 1331, in _find_and_load_unlocked
  File "<frozen importlib._bootstrap>", line 935, in _load_unlocked
  File "<frozen importlib._bootstrap_external>", line 995, in exec_module
  File "<frozen importlib._bootstrap>", line 488, in _call_with_frames_removed
  File "/mnt/c/Users/HAng3/Documents/wafer-defect-library/backend/app.py", line 5, in <module>
    from flask_cors import CORS
ModuleNotFoundError: No module named 'flask_cors'
[2025-04-09 08:38:18 +0800] [1558] [ERROR] Exception in worker process
Traceback (most recent call last):
  File "/mnt/c/Users/HAng3/Documents/wafer-defect-library/backend/venv/lib/python3.12/site-packages/gunicorn/arbiter.py", line 608, in spawn_worker
    worker.init_process()
  File "/mnt/c/Users/HAng3/Documents/wafer-defect-library/backend/venv/lib/python3.12/site-packages/gunicorn/workers/base.py", line 135, in init_process
    self.load_wsgi()
  File "/mnt/c/Users/HAng3/Documents/wafer-defect-library/backend/venv/lib/python3.12/site-packages/gunicorn/workers/base.py", line 147, in load_wsgi
    self.wsgi = self.app.wsgi()
                ^^^^^^^^^^^^^^^
  File "/mnt/c/Users/HAng3/Documents/wafer-defect-library/backend/venv/lib/python3.12/site-packages/gunicorn/app/base.py", line 66, in wsgi
    self.callable = self.load()
                    ^^^^^^^^^^^
  File "/mnt/c/Users/HAng3/Documents/wafer-defect-library/backend/venv/lib/python3.12/site-packages/gunicorn/app/wsgiapp.py", line 57, in load
    return self.load_wsgiapp()
           ^^^^^^^^^^^^^^^^^^^
  File "/mnt/c/Users/HAng3/Documents/wafer-defect-library/backend/venv/lib/python3.12/site-packages/gunicorn/app/wsgiapp.py", line 47, in load_wsgiapp
    return util.import_app(self.app_uri)
           ^^^^^^^^^^^^^^^^^^^^^^^^^^^^^
  File "/mnt/c/Users/HAng3/Documents/wafer-defect-library/backend/venv/lib/python3.12/site-packages/gunicorn/util.py", line 370, in import_app
    mod = importlib.import_module(module)
          ^^^^^^^^^^^^^^^^^^^^^^^^^^^^^^^
  File "/usr/lib/python3.12/importlib/__init__.py", line 90, in import_module
    return _bootstrap._gcd_import(name[level:], package, level)
           ^^^^^^^^^^^^^^^^^^^^^^^^^^^^^^^^^^^^^^^^^^^^^^^^^^^^
  File "<frozen importlib._bootstrap>", line 1387, in _gcd_import
  File "<frozen importlib._bootstrap>", line 1360, in _find_and_load
  File "<frozen importlib._bootstrap>", line 1331, in _find_and_load_unlocked
  File "<frozen importlib._bootstrap>", line 935, in _load_unlocked
  File "<frozen importlib._bootstrap_external>", line 995, in exec_module
  File "<frozen importlib._bootstrap>", line 488, in _call_with_frames_removed
  File "/mnt/c/Users/HAng3/Documents/wafer-defect-library/backend/app.py", line 5, in <module>
    from flask_cors import CORS
ModuleNotFoundError: No module named 'flask_cors'
[2025-04-09 08:38:18 +0800] [1556] [ERROR] Exception in worker process
Traceback (most recent call last):
  File "/mnt/c/Users/HAng3/Documents/wafer-defect-library/backend/venv/lib/python3.12/site-packages/gunicorn/arbiter.py", line 608, in spawn_worker
    worker.init_process()
  File "/mnt/c/Users/HAng3/Documents/wafer-defect-library/backend/venv/lib/python3.12/site-packages/gunicorn/workers/base.py", line 135, in init_process
    self.load_wsgi()
  File "/mnt/c/Users/HAng3/Documents/wafer-defect-library/backend/venv/lib/python3.12/site-packages/gunicorn/workers/base.py", line 147, in load_wsgi
    self.wsgi = self.app.wsgi()
                ^^^^^^^^^^^^^^^
  File "/mnt/c/Users/HAng3/Documents/wafer-defect-library/backend/venv/lib/python3.12/site-packages/gunicorn/app/base.py", line 66, in wsgi
    self.callable = self.load()
                    ^^^^^^^^^^^
  File "/mnt/c/Users/HAng3/Documents/wafer-defect-library/backend/venv/lib/python3.12/site-packages/gunicorn/app/wsgiapp.py", line 57, in load
    return self.load_wsgiapp()
           ^^^^^^^^^^^^^^^^^^^
  File "/mnt/c/Users/HAng3/Documents/wafer-defect-library/backend/venv/lib/python3.12/site-packages/gunicorn/app/wsgiapp.py", line 47, in load_wsgiapp
    return util.import_app(self.app_uri)
           ^^^^^^^^^^^^^^^^^^^^^^^^^^^^^
  File "/mnt/c/Users/HAng3/Documents/wafer-defect-library/backend/venv/lib/python3.12/site-packages/gunicorn/util.py", line 370, in import_app
    mod = importlib.import_module(module)
          ^^^^^^^^^^^^^^^^^^^^^^^^^^^^^^^
  File "/usr/lib/python3.12/importlib/__init__.py", line 90, in import_module
    return _bootstrap._gcd_import(name[level:], package, level)
           ^^^^^^^^^^^^^^^^^^^^^^^^^^^^^^^^^^^^^^^^^^^^^^^^^^^^
  File "<frozen importlib._bootstrap>", line 1387, in _gcd_import
  File "<frozen importlib._bootstrap>", line 1360, in _find_and_load
  File "<frozen importlib._bootstrap>", line 1331, in _find_and_load_unlocked
  File "<frozen importlib._bootstrap>", line 935, in _load_unlocked
  File "<frozen importlib._bootstrap_external>", line 995, in exec_module
  File "<frozen importlib._bootstrap>", line 488, in _call_with_frames_removed
  File "/mnt/c/Users/HAng3/Documents/wafer-defect-library/backend/app.py", line 5, in <module>
    from flask_cors import CORS
ModuleNotFoundError: No module named 'flask_cors'
[2025-04-09 08:38:18 +0800] [1550] [ERROR] Exception in worker process
Traceback (most recent call last):
  File "/mnt/c/Users/HAng3/Documents/wafer-defect-library/backend/venv/lib/python3.12/site-packages/gunicorn/arbiter.py", line 608, in spawn_worker
    worker.init_process()
  File "/mnt/c/Users/HAng3/Documents/wafer-defect-library/backend/venv/lib/python3.12/site-packages/gunicorn/workers/base.py", line 135, in init_process
    self.load_wsgi()
  File "/mnt/c/Users/HAng3/Documents/wafer-defect-library/backend/venv/lib/python3.12/site-packages/gunicorn/workers/base.py", line 147, in load_wsgi
    self.wsgi = self.app.wsgi()
                ^^^^^^^^^^^^^^^
  File "/mnt/c/Users/HAng3/Documents/wafer-defect-library/backend/venv/lib/python3.12/site-packages/gunicorn/app/base.py", line 66, in wsgi
    self.callable = self.load()
                    ^^^^^^^^^^^
  File "/mnt/c/Users/HAng3/Documents/wafer-defect-library/backend/venv/lib/python3.12/site-packages/gunicorn/app/wsgiapp.py", line 57, in load
    return self.load_wsgiapp()
           ^^^^^^^^^^^^^^^^^^^
  File "/mnt/c/Users/HAng3/Documents/wafer-defect-library/backend/venv/lib/python3.12/site-packages/gunicorn/app/wsgiapp.py", line 47, in load_wsgiapp
    return util.import_app(self.app_uri)
           ^^^^^^^^^^^^^^^^^^^^^^^^^^^^^
  File "/mnt/c/Users/HAng3/Documents/wafer-defect-library/backend/venv/lib/python3.12/site-packages/gunicorn/util.py", line 370, in import_app
    mod = importlib.import_module(module)
          ^^^^^^^^^^^^^^^^^^^^^^^^^^^^^^^
  File "/usr/lib/python3.12/importlib/__init__.py", line 90, in import_module
    return _bootstrap._gcd_import(name[level:], package, level)
           ^^^^^^^^^^^^^^^^^^^^^^^^^^^^^^^^^^^^^^^^^^^^^^^^^^^^
  File "<frozen importlib._bootstrap>", line 1387, in _gcd_import
  File "<frozen importlib._bootstrap>", line 1360, in _find_and_load
  File "<frozen importlib._bootstrap>", line 1331, in _find_and_load_unlocked
  File "<frozen importlib._bootstrap>", line 935, in _load_unlocked
  File "<frozen importlib._bootstrap_external>", line 995, in exec_module
  File "<frozen importlib._bootstrap>", line 488, in _call_with_frames_removed
  File "/mnt/c/Users/HAng3/Documents/wafer-defect-library/backend/app.py", line 5, in <module>
    from flask_cors import CORS
ModuleNotFoundError: No module named 'flask_cors'
[2025-04-09 08:38:18 +0800] [1559] [ERROR] Exception in worker process
Traceback (most recent call last):
  File "/mnt/c/Users/HAng3/Documents/wafer-defect-library/backend/venv/lib/python3.12/site-packages/gunicorn/arbiter.py", line 608, in spawn_worker
    worker.init_process()
  File "/mnt/c/Users/HAng3/Documents/wafer-defect-library/backend/venv/lib/python3.12/site-packages/gunicorn/workers/base.py", line 135, in init_process
    self.load_wsgi()
  File "/mnt/c/Users/HAng3/Documents/wafer-defect-library/backend/venv/lib/python3.12/site-packages/gunicorn/workers/base.py", line 147, in load_wsgi
    self.wsgi = self.app.wsgi()
                ^^^^^^^^^^^^^^^
  File "/mnt/c/Users/HAng3/Documents/wafer-defect-library/backend/venv/lib/python3.12/site-packages/gunicorn/app/base.py", line 66, in wsgi
    self.callable = self.load()
                    ^^^^^^^^^^^
  File "/mnt/c/Users/HAng3/Documents/wafer-defect-library/backend/venv/lib/python3.12/site-packages/gunicorn/app/wsgiapp.py", line 57, in load
    return self.load_wsgiapp()
           ^^^^^^^^^^^^^^^^^^^
  File "/mnt/c/Users/HAng3/Documents/wafer-defect-library/backend/venv/lib/python3.12/site-packages/gunicorn/app/wsgiapp.py", line 47, in load_wsgiapp
    return util.import_app(self.app_uri)
           ^^^^^^^^^^^^^^^^^^^^^^^^^^^^^
  File "/mnt/c/Users/HAng3/Documents/wafer-defect-library/backend/venv/lib/python3.12/site-packages/gunicorn/util.py", line 370, in import_app
    mod = importlib.import_module(module)
          ^^^^^^^^^^^^^^^^^^^^^^^^^^^^^^^
  File "/usr/lib/python3.12/importlib/__init__.py", line 90, in import_module
    return _bootstrap._gcd_import(name[level:], package, level)
           ^^^^^^^^^^^^^^^^^^^^^^^^^^^^^^^^^^^^^^^^^^^^^^^^^^^^
  File "<frozen importlib._bootstrap>", line 1387, in _gcd_import
  File "<frozen importlib._bootstrap>", line 1360, in _find_and_load
  File "<frozen importlib._bootstrap>", line 1331, in _find_and_load_unlocked
  File "<frozen importlib._bootstrap>", line 935, in _load_unlocked
  File "<frozen importlib._bootstrap_external>", line 995, in exec_module
  File "<frozen importlib._bootstrap>", line 488, in _call_with_frames_removed
  File "/mnt/c/Users/HAng3/Documents/wafer-defect-library/backend/app.py", line 5, in <module>
    from flask_cors import CORS
ModuleNotFoundError: No module named 'flask_cors'
[2025-04-09 08:38:18 +0800] [1553] [ERROR] Exception in worker process
Traceback (most recent call last):
  File "/mnt/c/Users/HAng3/Documents/wafer-defect-library/backend/venv/lib/python3.12/site-packages/gunicorn/arbiter.py", line 608, in spawn_worker
    worker.init_process()
  File "/mnt/c/Users/HAng3/Documents/wafer-defect-library/backend/venv/lib/python3.12/site-packages/gunicorn/workers/base.py", line 135, in init_process
    self.load_wsgi()
  File "/mnt/c/Users/HAng3/Documents/wafer-defect-library/backend/venv/lib/python3.12/site-packages/gunicorn/workers/base.py", line 147, in load_wsgi
    self.wsgi = self.app.wsgi()
                ^^^^^^^^^^^^^^^
  File "/mnt/c/Users/HAng3/Documents/wafer-defect-library/backend/venv/lib/python3.12/site-packages/gunicorn/app/base.py", line 66, in wsgi
    self.callable = self.load()
                    ^^^^^^^^^^^
  File "/mnt/c/Users/HAng3/Documents/wafer-defect-library/backend/venv/lib/python3.12/site-packages/gunicorn/app/wsgiapp.py", line 57, in load
    return self.load_wsgiapp()
           ^^^^^^^^^^^^^^^^^^^
  File "/mnt/c/Users/HAng3/Documents/wafer-defect-library/backend/venv/lib/python3.12/site-packages/gunicorn/app/wsgiapp.py", line 47, in load_wsgiapp
    return util.import_app(self.app_uri)
           ^^^^^^^^^^^^^^^^^^^^^^^^^^^^^
  File "/mnt/c/Users/HAng3/Documents/wafer-defect-library/backend/venv/lib/python3.12/site-packages/gunicorn/util.py", line 370, in import_app
    mod = importlib.import_module(module)
          ^^^^^^^^^^^^^^^^^^^^^^^^^^^^^^^
  File "/usr/lib/python3.12/importlib/__init__.py", line 90, in import_module
    return _bootstrap._gcd_import(name[level:], package, level)
           ^^^^^^^^^^^^^^^^^^^^^^^^^^^^^^^^^^^^^^^^^^^^^^^^^^^^
  File "<frozen importlib._bootstrap>", line 1387, in _gcd_import
  File "<frozen importlib._bootstrap>", line 1360, in _find_and_load
  File "<frozen importlib._bootstrap>", line 1331, in _find_and_load_unlocked
  File "<frozen importlib._bootstrap>", line 935, in _load_unlocked
  File "<frozen importlib._bootstrap_external>", line 995, in exec_module
  File "<frozen importlib._bootstrap>", line 488, in _call_with_frames_removed
  File "/mnt/c/Users/HAng3/Documents/wafer-defect-library/backend/app.py", line 5, in <module>
    from flask_cors import CORS
ModuleNotFoundError: No module named 'flask_cors'
[2025-04-09 08:38:18 +0800] [1562] [ERROR] Exception in worker process
Traceback (most recent call last):
  File "/mnt/c/Users/HAng3/Documents/wafer-defect-library/backend/venv/lib/python3.12/site-packages/gunicorn/arbiter.py", line 608, in spawn_worker
    worker.init_process()
  File "/mnt/c/Users/HAng3/Documents/wafer-defect-library/backend/venv/lib/python3.12/site-packages/gunicorn/workers/base.py", line 135, in init_process
    self.load_wsgi()
  File "/mnt/c/Users/HAng3/Documents/wafer-defect-library/backend/venv/lib/python3.12/site-packages/gunicorn/workers/base.py", line 147, in load_wsgi
    self.wsgi = self.app.wsgi()
                ^^^^^^^^^^^^^^^
  File "/mnt/c/Users/HAng3/Documents/wafer-defect-library/backend/venv/lib/python3.12/site-packages/gunicorn/app/base.py", line 66, in wsgi
    self.callable = self.load()
                    ^^^^^^^^^^^
  File "/mnt/c/Users/HAng3/Documents/wafer-defect-library/backend/venv/lib/python3.12/site-packages/gunicorn/app/wsgiapp.py", line 57, in load
    return self.load_wsgiapp()
           ^^^^^^^^^^^^^^^^^^^
  File "/mnt/c/Users/HAng3/Documents/wafer-defect-library/backend/venv/lib/python3.12/site-packages/gunicorn/app/wsgiapp.py", line 47, in load_wsgiapp
    return util.import_app(self.app_uri)
           ^^^^^^^^^^^^^^^^^^^^^^^^^^^^^
  File "/mnt/c/Users/HAng3/Documents/wafer-defect-library/backend/venv/lib/python3.12/site-packages/gunicorn/util.py", line 370, in import_app
    mod = importlib.import_module(module)
          ^^^^^^^^^^^^^^^^^^^^^^^^^^^^^^^
  File "/usr/lib/python3.12/importlib/__init__.py", line 90, in import_module
    return _bootstrap._gcd_import(name[level:], package, level)
           ^^^^^^^^^^^^^^^^^^^^^^^^^^^^^^^^^^^^^^^^^^^^^^^^^^^^
  File "<frozen importlib._bootstrap>", line 1387, in _gcd_import
  File "<frozen importlib._bootstrap>", line 1360, in _find_and_load
  File "<frozen importlib._bootstrap>", line 1331, in _find_and_load_unlocked
  File "<frozen importlib._bootstrap>", line 935, in _load_unlocked
  File "<frozen importlib._bootstrap_external>", line 995, in exec_module
  File "<frozen importlib._bootstrap>", line 488, in _call_with_frames_removed
  File "/mnt/c/Users/HAng3/Documents/wafer-defect-library/backend/app.py", line 5, in <module>
    from flask_cors import CORS
ModuleNotFoundError: No module named 'flask_cors'
[2025-04-09 08:38:18 +0800] [1548] [ERROR] Exception in worker process
Traceback (most recent call last):
  File "/mnt/c/Users/HAng3/Documents/wafer-defect-library/backend/venv/lib/python3.12/site-packages/gunicorn/arbiter.py", line 608, in spawn_worker
    worker.init_process()
  File "/mnt/c/Users/HAng3/Documents/wafer-defect-library/backend/venv/lib/python3.12/site-packages/gunicorn/workers/base.py", line 135, in init_process
    self.load_wsgi()
  File "/mnt/c/Users/HAng3/Documents/wafer-defect-library/backend/venv/lib/python3.12/site-packages/gunicorn/workers/base.py", line 147, in load_wsgi
    self.wsgi = self.app.wsgi()
                ^^^^^^^^^^^^^^^
  File "/mnt/c/Users/HAng3/Documents/wafer-defect-library/backend/venv/lib/python3.12/site-packages/gunicorn/app/base.py", line 66, in wsgi
    self.callable = self.load()
                    ^^^^^^^^^^^
  File "/mnt/c/Users/HAng3/Documents/wafer-defect-library/backend/venv/lib/python3.12/site-packages/gunicorn/app/wsgiapp.py", line 57, in load
    return self.load_wsgiapp()
           ^^^^^^^^^^^^^^^^^^^
  File "/mnt/c/Users/HAng3/Documents/wafer-defect-library/backend/venv/lib/python3.12/site-packages/gunicorn/app/wsgiapp.py", line 47, in load_wsgiapp
    return util.import_app(self.app_uri)
           ^^^^^^^^^^^^^^^^^^^^^^^^^^^^^
  File "/mnt/c/Users/HAng3/Documents/wafer-defect-library/backend/venv/lib/python3.12/site-packages/gunicorn/util.py", line 370, in import_app
    mod = importlib.import_module(module)
          ^^^^^^^^^^^^^^^^^^^^^^^^^^^^^^^
  File "/usr/lib/python3.12/importlib/__init__.py", line 90, in import_module
    return _bootstrap._gcd_import(name[level:], package, level)
           ^^^^^^^^^^^^^^^^^^^^^^^^^^^^^^^^^^^^^^^^^^^^^^^^^^^^
  File "<frozen importlib._bootstrap>", line 1387, in _gcd_import
  File "<frozen importlib._bootstrap>", line 1360, in _find_and_load
  File "<frozen importlib._bootstrap>", line 1331, in _find_and_load_unlocked
  File "<frozen importlib._bootstrap>", line 935, in _load_unlocked
  File "<frozen importlib._bootstrap_external>", line 995, in exec_module
  File "<frozen importlib._bootstrap>", line 488, in _call_with_frames_removed
  File "/mnt/c/Users/HAng3/Documents/wafer-defect-library/backend/app.py", line 5, in <module>
    from flask_cors import CORS
ModuleNotFoundError: No module named 'flask_cors'
[2025-04-09 08:38:18 +0800] [1552] [ERROR] Exception in worker process
Traceback (most recent call last):
  File "/mnt/c/Users/HAng3/Documents/wafer-defect-library/backend/venv/lib/python3.12/site-packages/gunicorn/arbiter.py", line 608, in spawn_worker
    worker.init_process()
  File "/mnt/c/Users/HAng3/Documents/wafer-defect-library/backend/venv/lib/python3.12/site-packages/gunicorn/workers/base.py", line 135, in init_process
    self.load_wsgi()
  File "/mnt/c/Users/HAng3/Documents/wafer-defect-library/backend/venv/lib/python3.12/site-packages/gunicorn/workers/base.py", line 147, in load_wsgi
    self.wsgi = self.app.wsgi()
                ^^^^^^^^^^^^^^^
  File "/mnt/c/Users/HAng3/Documents/wafer-defect-library/backend/venv/lib/python3.12/site-packages/gunicorn/app/base.py", line 66, in wsgi
    self.callable = self.load()
                    ^^^^^^^^^^^
  File "/mnt/c/Users/HAng3/Documents/wafer-defect-library/backend/venv/lib/python3.12/site-packages/gunicorn/app/wsgiapp.py", line 57, in load
    return self.load_wsgiapp()
           ^^^^^^^^^^^^^^^^^^^
  File "/mnt/c/Users/HAng3/Documents/wafer-defect-library/backend/venv/lib/python3.12/site-packages/gunicorn/app/wsgiapp.py", line 47, in load_wsgiapp
    return util.import_app(self.app_uri)
           ^^^^^^^^^^^^^^^^^^^^^^^^^^^^^
  File "/mnt/c/Users/HAng3/Documents/wafer-defect-library/backend/venv/lib/python3.12/site-packages/gunicorn/util.py", line 370, in import_app
    mod = importlib.import_module(module)
          ^^^^^^^^^^^^^^^^^^^^^^^^^^^^^^^
  File "/usr/lib/python3.12/importlib/__init__.py", line 90, in import_module
    return _bootstrap._gcd_import(name[level:], package, level)
           ^^^^^^^^^^^^^^^^^^^^^^^^^^^^^^^^^^^^^^^^^^^^^^^^^^^^
  File "<frozen importlib._bootstrap>", line 1387, in _gcd_import
  File "<frozen importlib._bootstrap>", line 1360, in _find_and_load
  File "<frozen importlib._bootstrap>", line 1331, in _find_and_load_unlocked
  File "<frozen importlib._bootstrap>", line 935, in _load_unlocked
  File "<frozen importlib._bootstrap_external>", line 995, in exec_module
  File "<frozen importlib._bootstrap>", line 488, in _call_with_frames_removed
  File "/mnt/c/Users/HAng3/Documents/wafer-defect-library/backend/app.py", line 5, in <module>
    from flask_cors import CORS
ModuleNotFoundError: No module named 'flask_cors'
[2025-04-09 08:38:18 +0800] [1561] [ERROR] Exception in worker process
Traceback (most recent call last):
  File "/mnt/c/Users/HAng3/Documents/wafer-defect-library/backend/venv/lib/python3.12/site-packages/gunicorn/arbiter.py", line 608, in spawn_worker
    worker.init_process()
  File "/mnt/c/Users/HAng3/Documents/wafer-defect-library/backend/venv/lib/python3.12/site-packages/gunicorn/workers/base.py", line 135, in init_process
    self.load_wsgi()
  File "/mnt/c/Users/HAng3/Documents/wafer-defect-library/backend/venv/lib/python3.12/site-packages/gunicorn/workers/base.py", line 147, in load_wsgi
    self.wsgi = self.app.wsgi()
                ^^^^^^^^^^^^^^^
  File "/mnt/c/Users/HAng3/Documents/wafer-defect-library/backend/venv/lib/python3.12/site-packages/gunicorn/app/base.py", line 66, in wsgi
    self.callable = self.load()
                    ^^^^^^^^^^^
  File "/mnt/c/Users/HAng3/Documents/wafer-defect-library/backend/venv/lib/python3.12/site-packages/gunicorn/app/wsgiapp.py", line 57, in load
    return self.load_wsgiapp()
           ^^^^^^^^^^^^^^^^^^^
  File "/mnt/c/Users/HAng3/Documents/wafer-defect-library/backend/venv/lib/python3.12/site-packages/gunicorn/app/wsgiapp.py", line 47, in load_wsgiapp
    return util.import_app(self.app_uri)
           ^^^^^^^^^^^^^^^^^^^^^^^^^^^^^
  File "/mnt/c/Users/HAng3/Documents/wafer-defect-library/backend/venv/lib/python3.12/site-packages/gunicorn/util.py", line 370, in import_app
    mod = importlib.import_module(module)
          ^^^^^^^^^^^^^^^^^^^^^^^^^^^^^^^
  File "/usr/lib/python3.12/importlib/__init__.py", line 90, in import_module
    return _bootstrap._gcd_import(name[level:], package, level)
           ^^^^^^^^^^^^^^^^^^^^^^^^^^^^^^^^^^^^^^^^^^^^^^^^^^^^
  File "<frozen importlib._bootstrap>", line 1387, in _gcd_import
  File "<frozen importlib._bootstrap>", line 1360, in _find_and_load
  File "<frozen importlib._bootstrap>", line 1331, in _find_and_load_unlocked
  File "<frozen importlib._bootstrap>", line 935, in _load_unlocked
  File "<frozen importlib._bootstrap_external>", line 995, in exec_module
  File "<frozen importlib._bootstrap>", line 488, in _call_with_frames_removed
  File "/mnt/c/Users/HAng3/Documents/wafer-defect-library/backend/app.py", line 5, in <module>
    from flask_cors import CORS
ModuleNotFoundError: No module named 'flask_cors'
[2025-04-09 08:38:18 +0800] [1555] [ERROR] Exception in worker process
Traceback (most recent call last):
  File "/mnt/c/Users/HAng3/Documents/wafer-defect-library/backend/venv/lib/python3.12/site-packages/gunicorn/arbiter.py", line 608, in spawn_worker
    worker.init_process()
  File "/mnt/c/Users/HAng3/Documents/wafer-defect-library/backend/venv/lib/python3.12/site-packages/gunicorn/workers/base.py", line 135, in init_process
    self.load_wsgi()
  File "/mnt/c/Users/HAng3/Documents/wafer-defect-library/backend/venv/lib/python3.12/site-packages/gunicorn/workers/base.py", line 147, in load_wsgi
    self.wsgi = self.app.wsgi()
                ^^^^^^^^^^^^^^^
  File "/mnt/c/Users/HAng3/Documents/wafer-defect-library/backend/venv/lib/python3.12/site-packages/gunicorn/app/base.py", line 66, in wsgi
    self.callable = self.load()
                    ^^^^^^^^^^^
  File "/mnt/c/Users/HAng3/Documents/wafer-defect-library/backend/venv/lib/python3.12/site-packages/gunicorn/app/wsgiapp.py", line 57, in load
    return self.load_wsgiapp()
           ^^^^^^^^^^^^^^^^^^^
  File "/mnt/c/Users/HAng3/Documents/wafer-defect-library/backend/venv/lib/python3.12/site-packages/gunicorn/app/wsgiapp.py", line 47, in load_wsgiapp
    return util.import_app(self.app_uri)
           ^^^^^^^^^^^^^^^^^^^^^^^^^^^^^
  File "/mnt/c/Users/HAng3/Documents/wafer-defect-library/backend/venv/lib/python3.12/site-packages/gunicorn/util.py", line 370, in import_app
    mod = importlib.import_module(module)
          ^^^^^^^^^^^^^^^^^^^^^^^^^^^^^^^
  File "/usr/lib/python3.12/importlib/__init__.py", line 90, in import_module
    return _bootstrap._gcd_import(name[level:], package, level)
           ^^^^^^^^^^^^^^^^^^^^^^^^^^^^^^^^^^^^^^^^^^^^^^^^^^^^
  File "<frozen importlib._bootstrap>", line 1387, in _gcd_import
  File "<frozen importlib._bootstrap>", line 1360, in _find_and_load
  File "<frozen importlib._bootstrap>", line 1331, in _find_and_load_unlocked
  File "<frozen importlib._bootstrap>", line 935, in _load_unlocked
  File "<frozen importlib._bootstrap_external>", line 995, in exec_module
  File "<frozen importlib._bootstrap>", line 488, in _call_with_frames_removed
  File "/mnt/c/Users/HAng3/Documents/wafer-defect-library/backend/app.py", line 5, in <module>
    from flask_cors import CORS
ModuleNotFoundError: No module named 'flask_cors'
[2025-04-09 08:38:18 +0800] [1551] [ERROR] Exception in worker process
Traceback (most recent call last):
  File "/mnt/c/Users/HAng3/Documents/wafer-defect-library/backend/venv/lib/python3.12/site-packages/gunicorn/arbiter.py", line 608, in spawn_worker
    worker.init_process()
  File "/mnt/c/Users/HAng3/Documents/wafer-defect-library/backend/venv/lib/python3.12/site-packages/gunicorn/workers/base.py", line 135, in init_process
    self.load_wsgi()
  File "/mnt/c/Users/HAng3/Documents/wafer-defect-library/backend/venv/lib/python3.12/site-packages/gunicorn/workers/base.py", line 147, in load_wsgi
    self.wsgi = self.app.wsgi()
                ^^^^^^^^^^^^^^^
  File "/mnt/c/Users/HAng3/Documents/wafer-defect-library/backend/venv/lib/python3.12/site-packages/gunicorn/app/base.py", line 66, in wsgi
    self.callable = self.load()
                    ^^^^^^^^^^^
  File "/mnt/c/Users/HAng3/Documents/wafer-defect-library/backend/venv/lib/python3.12/site-packages/gunicorn/app/wsgiapp.py", line 57, in load
    return self.load_wsgiapp()
           ^^^^^^^^^^^^^^^^^^^
  File "/mnt/c/Users/HAng3/Documents/wafer-defect-library/backend/venv/lib/python3.12/site-packages/gunicorn/app/wsgiapp.py", line 47, in load_wsgiapp
    return util.import_app(self.app_uri)
           ^^^^^^^^^^^^^^^^^^^^^^^^^^^^^
  File "/mnt/c/Users/HAng3/Documents/wafer-defect-library/backend/venv/lib/python3.12/site-packages/gunicorn/util.py", line 370, in import_app
    mod = importlib.import_module(module)
          ^^^^^^^^^^^^^^^^^^^^^^^^^^^^^^^
  File "/usr/lib/python3.12/importlib/__init__.py", line 90, in import_module
    return _bootstrap._gcd_import(name[level:], package, level)
           ^^^^^^^^^^^^^^^^^^^^^^^^^^^^^^^^^^^^^^^^^^^^^^^^^^^^
  File "<frozen importlib._bootstrap>", line 1387, in _gcd_import
  File "<frozen importlib._bootstrap>", line 1360, in _find_and_load
  File "<frozen importlib._bootstrap>", line 1331, in _find_and_load_unlocked
  File "<frozen importlib._bootstrap>", line 935, in _load_unlocked
  File "<frozen importlib._bootstrap_external>", line 995, in exec_module
  File "<frozen importlib._bootstrap>", line 488, in _call_with_frames_removed
  File "/mnt/c/Users/HAng3/Documents/wafer-defect-library/backend/app.py", line 5, in <module>
    from flask_cors import CORS
ModuleNotFoundError: No module named 'flask_cors'
[2025-04-09 08:38:18 +0800] [1554] [ERROR] Exception in worker process
Traceback (most recent call last):
  File "/mnt/c/Users/HAng3/Documents/wafer-defect-library/backend/venv/lib/python3.12/site-packages/gunicorn/arbiter.py", line 608, in spawn_worker
    worker.init_process()
  File "/mnt/c/Users/HAng3/Documents/wafer-defect-library/backend/venv/lib/python3.12/site-packages/gunicorn/workers/base.py", line 135, in init_process
    self.load_wsgi()
  File "/mnt/c/Users/HAng3/Documents/wafer-defect-library/backend/venv/lib/python3.12/site-packages/gunicorn/workers/base.py", line 147, in load_wsgi
    self.wsgi = self.app.wsgi()
                ^^^^^^^^^^^^^^^
  File "/mnt/c/Users/HAng3/Documents/wafer-defect-library/backend/venv/lib/python3.12/site-packages/gunicorn/app/base.py", line 66, in wsgi
    self.callable = self.load()
                    ^^^^^^^^^^^
  File "/mnt/c/Users/HAng3/Documents/wafer-defect-library/backend/venv/lib/python3.12/site-packages/gunicorn/app/wsgiapp.py", line 57, in load
    return self.load_wsgiapp()
           ^^^^^^^^^^^^^^^^^^^
  File "/mnt/c/Users/HAng3/Documents/wafer-defect-library/backend/venv/lib/python3.12/site-packages/gunicorn/app/wsgiapp.py", line 47, in load_wsgiapp
    return util.import_app(self.app_uri)
           ^^^^^^^^^^^^^^^^^^^^^^^^^^^^^
  File "/mnt/c/Users/HAng3/Documents/wafer-defect-library/backend/venv/lib/python3.12/site-packages/gunicorn/util.py", line 370, in import_app
    mod = importlib.import_module(module)
          ^^^^^^^^^^^^^^^^^^^^^^^^^^^^^^^
  File "/usr/lib/python3.12/importlib/__init__.py", line 90, in import_module
    return _bootstrap._gcd_import(name[level:], package, level)
           ^^^^^^^^^^^^^^^^^^^^^^^^^^^^^^^^^^^^^^^^^^^^^^^^^^^^
  File "<frozen importlib._bootstrap>", line 1387, in _gcd_import
  File "<frozen importlib._bootstrap>", line 1360, in _find_and_load
  File "<frozen importlib._bootstrap>", line 1331, in _find_and_load_unlocked
  File "<frozen importlib._bootstrap>", line 935, in _load_unlocked
  File "<frozen importlib._bootstrap_external>", line 995, in exec_module
  File "<frozen importlib._bootstrap>", line 488, in _call_with_frames_removed
  File "/mnt/c/Users/HAng3/Documents/wafer-defect-library/backend/app.py", line 5, in <module>
    from flask_cors import CORS
ModuleNotFoundError: No module named 'flask_cors'
[2025-04-09 08:38:20 +0800] [1560] [INFO] Worker exiting (pid: 1560)
[2025-04-09 08:38:20 +0800] [1549] [INFO] Worker exiting (pid: 1549)
[2025-04-09 08:38:18 +0800] [1557] [ERROR] Exception in worker process
Traceback (most recent call last):
  File "/mnt/c/Users/HAng3/Documents/wafer-defect-library/backend/venv/lib/python3.12/site-packages/gunicorn/arbiter.py", line 608, in spawn_worker
    worker.init_process()
  File "/mnt/c/Users/HAng3/Documents/wafer-defect-library/backend/venv/lib/python3.12/site-packages/gunicorn/workers/base.py", line 135, in init_process
    self.load_wsgi()
  File "/mnt/c/Users/HAng3/Documents/wafer-defect-library/backend/venv/lib/python3.12/site-packages/gunicorn/workers/base.py", line 147, in load_wsgi
    self.wsgi = self.app.wsgi()
                ^^^^^^^^^^^^^^^
  File "/mnt/c/Users/HAng3/Documents/wafer-defect-library/backend/venv/lib/python3.12/site-packages/gunicorn/app/base.py", line 66, in wsgi
    self.callable = self.load()
                    ^^^^^^^^^^^
  File "/mnt/c/Users/HAng3/Documents/wafer-defect-library/backend/venv/lib/python3.12/site-packages/gunicorn/app/wsgiapp.py", line 57, in load
    return self.load_wsgiapp()
           ^^^^^^^^^^^^^^^^^^^
  File "/mnt/c/Users/HAng3/Documents/wafer-defect-library/backend/venv/lib/python3.12/site-packages/gunicorn/app/wsgiapp.py", line 47, in load_wsgiapp
    return util.import_app(self.app_uri)
           ^^^^^^^^^^^^^^^^^^^^^^^^^^^^^
  File "/mnt/c/Users/HAng3/Documents/wafer-defect-library/backend/venv/lib/python3.12/site-packages/gunicorn/util.py", line 370, in import_app
    mod = importlib.import_module(module)
          ^^^^^^^^^^^^^^^^^^^^^^^^^^^^^^^
  File "/usr/lib/python3.12/importlib/__init__.py", line 90, in import_module
    return _bootstrap._gcd_import(name[level:], package, level)
           ^^^^^^^^^^^^^^^^^^^^^^^^^^^^^^^^^^^^^^^^^^^^^^^^^^^^
  File "<frozen importlib._bootstrap>", line 1387, in _gcd_import
  File "<frozen importlib._bootstrap>", line 1360, in _find_and_load
  File "<frozen importlib._bootstrap>", line 1331, in _find_and_load_unlocked
  File "<frozen importlib._bootstrap>", line 935, in _load_unlocked
  File "<frozen importlib._bootstrap_external>", line 995, in exec_module
  File "<frozen importlib._bootstrap>", line 488, in _call_with_frames_removed
  File "/mnt/c/Users/HAng3/Documents/wafer-defect-library/backend/app.py", line 5, in <module>
    from flask_cors import CORS
ModuleNotFoundError: No module named 'flask_cors'
[2025-04-09 08:38:20 +0800] [1558] [INFO] Worker exiting (pid: 1558)
[2025-04-09 08:38:20 +0800] [1556] [INFO] Worker exiting (pid: 1556)
[2025-04-09 08:38:20 +0800] [1550] [INFO] Worker exiting (pid: 1550)
[2025-04-09 08:38:20 +0800] [1559] [INFO] Worker exiting (pid: 1559)
[2025-04-09 08:38:20 +0800] [1553] [INFO] Worker exiting (pid: 1553)
[2025-04-09 08:38:20 +0800] [1562] [INFO] Worker exiting (pid: 1562)
[2025-04-09 08:38:20 +0800] [1548] [INFO] Worker exiting (pid: 1548)
[2025-04-09 08:38:20 +0800] [1552] [INFO] Worker exiting (pid: 1552)
[2025-04-09 08:38:20 +0800] [1561] [INFO] Worker exiting (pid: 1561)
[2025-04-09 08:38:20 +0800] [1555] [INFO] Worker exiting (pid: 1555)
[2025-04-09 08:38:20 +0800] [1551] [INFO] Worker exiting (pid: 1551)
[2025-04-09 08:38:20 +0800] [1554] [INFO] Worker exiting (pid: 1554)
[2025-04-09 08:38:20 +0800] [1557] [INFO] Worker exiting (pid: 1557)
[2025-04-09 08:38:20 +0800] [1547] [ERROR] Worker (pid:1556) exited with code 3
[2025-04-09 08:38:20 +0800] [1547] [ERROR] Worker (pid:1550) was sent SIGTERM!
[2025-04-09 08:38:20 +0800] [1547] [ERROR] Worker (pid:1551) was sent SIGTERM!
[2025-04-09 08:38:22 +0800] [1563] [ERROR] Exception in worker process
Traceback (most recent call last):
  File "/mnt/c/Users/HAng3/Documents/wafer-defect-library/backend/venv/lib/python3.12/site-packages/gunicorn/arbiter.py", line 608, in spawn_worker
    worker.init_process()
  File "/mnt/c/Users/HAng3/Documents/wafer-defect-library/backend/venv/lib/python3.12/site-packages/gunicorn/workers/base.py", line 135, in init_process
    self.load_wsgi()
  File "/mnt/c/Users/HAng3/Documents/wafer-defect-library/backend/venv/lib/python3.12/site-packages/gunicorn/workers/base.py", line 147, in load_wsgi
    self.wsgi = self.app.wsgi()
                ^^^^^^^^^^^^^^^
  File "/mnt/c/Users/HAng3/Documents/wafer-defect-library/backend/venv/lib/python3.12/site-packages/gunicorn/app/base.py", line 66, in wsgi
    self.callable = self.load()
                    ^^^^^^^^^^^
  File "/mnt/c/Users/HAng3/Documents/wafer-defect-library/backend/venv/lib/python3.12/site-packages/gunicorn/app/wsgiapp.py", line 57, in load
    return self.load_wsgiapp()
           ^^^^^^^^^^^^^^^^^^^
  File "/mnt/c/Users/HAng3/Documents/wafer-defect-library/backend/venv/lib/python3.12/site-packages/gunicorn/app/wsgiapp.py", line 47, in load_wsgiapp
    return util.import_app(self.app_uri)
           ^^^^^^^^^^^^^^^^^^^^^^^^^^^^^
  File "/mnt/c/Users/HAng3/Documents/wafer-defect-library/backend/venv/lib/python3.12/site-packages/gunicorn/util.py", line 370, in import_app
    mod = importlib.import_module(module)
          ^^^^^^^^^^^^^^^^^^^^^^^^^^^^^^^
  File "/usr/lib/python3.12/importlib/__init__.py", line 90, in import_module
    return _bootstrap._gcd_import(name[level:], package, level)
           ^^^^^^^^^^^^^^^^^^^^^^^^^^^^^^^^^^^^^^^^^^^^^^^^^^^^
  File "<frozen importlib._bootstrap>", line 1387, in _gcd_import
  File "<frozen importlib._bootstrap>", line 1360, in _find_and_load
  File "<frozen importlib._bootstrap>", line 1331, in _find_and_load_unlocked
  File "<frozen importlib._bootstrap>", line 935, in _load_unlocked
  File "<frozen importlib._bootstrap_external>", line 995, in exec_module
  File "<frozen importlib._bootstrap>", line 488, in _call_with_frames_removed
  File "/mnt/c/Users/HAng3/Documents/wafer-defect-library/backend/app.py", line 5, in <module>
    from flask_cors import CORS
ModuleNotFoundError: No module named 'flask_cors'
[2025-04-09 08:38:22 +0800] [1563] [INFO] Worker exiting (pid: 1563)
[2025-04-09 08:38:22 +0800] [1547] [ERROR] Worker (pid:1563) exited with code 3
[2025-04-09 08:38:23 +0800] [1564] [ERROR] Exception in worker process
Traceback (most recent call last):
  File "/mnt/c/Users/HAng3/Documents/wafer-defect-library/backend/venv/lib/python3.12/site-packages/gunicorn/arbiter.py", line 608, in spawn_worker
    worker.init_process()
  File "/mnt/c/Users/HAng3/Documents/wafer-defect-library/backend/venv/lib/python3.12/site-packages/gunicorn/workers/base.py", line 135, in init_process
    self.load_wsgi()
  File "/mnt/c/Users/HAng3/Documents/wafer-defect-library/backend/venv/lib/python3.12/site-packages/gunicorn/workers/base.py", line 147, in load_wsgi
    self.wsgi = self.app.wsgi()
                ^^^^^^^^^^^^^^^
  File "/mnt/c/Users/HAng3/Documents/wafer-defect-library/backend/venv/lib/python3.12/site-packages/gunicorn/app/base.py", line 66, in wsgi
    self.callable = self.load()
                    ^^^^^^^^^^^
  File "/mnt/c/Users/HAng3/Documents/wafer-defect-library/backend/venv/lib/python3.12/site-packages/gunicorn/app/wsgiapp.py", line 57, in load
    return self.load_wsgiapp()
           ^^^^^^^^^^^^^^^^^^^
  File "/mnt/c/Users/HAng3/Documents/wafer-defect-library/backend/venv/lib/python3.12/site-packages/gunicorn/app/wsgiapp.py", line 47, in load_wsgiapp
    return util.import_app(self.app_uri)
           ^^^^^^^^^^^^^^^^^^^^^^^^^^^^^
  File "/mnt/c/Users/HAng3/Documents/wafer-defect-library/backend/venv/lib/python3.12/site-packages/gunicorn/util.py", line 370, in import_app
    mod = importlib.import_module(module)
          ^^^^^^^^^^^^^^^^^^^^^^^^^^^^^^^
  File "/usr/lib/python3.12/importlib/__init__.py", line 90, in import_module
    return _bootstrap._gcd_import(name[level:], package, level)
           ^^^^^^^^^^^^^^^^^^^^^^^^^^^^^^^^^^^^^^^^^^^^^^^^^^^^
  File "<frozen importlib._bootstrap>", line 1387, in _gcd_import
  File "<frozen importlib._bootstrap>", line 1360, in _find_and_load
  File "<frozen importlib._bootstrap>", line 1331, in _find_and_load_unlocked
  File "<frozen importlib._bootstrap>", line 935, in _load_unlocked
  File "<frozen importlib._bootstrap_external>", line 995, in exec_module
  File "<frozen importlib._bootstrap>", line 488, in _call_with_frames_removed
  File "/mnt/c/Users/HAng3/Documents/wafer-defect-library/backend/app.py", line 5, in <module>
    from flask_cors import CORS
ModuleNotFoundError: No module named 'flask_cors'
[2025-04-09 08:38:23 +0800] [1564] [INFO] Worker exiting (pid: 1564)
[2025-04-09 08:40:18 +0800] [1566] [INFO] Starting gunicorn 23.0.0
[2025-04-09 08:40:18 +0800] [1566] [INFO] Listening at: http://127.0.0.1:8000 (1566)
[2025-04-09 08:40:18 +0800] [1566] [INFO] Using worker: sync
[2025-04-09 08:40:18 +0800] [1567] [INFO] Booting worker with pid: 1567
[2025-04-09 08:40:18 +0800] [1568] [INFO] Booting worker with pid: 1568
[2025-04-09 08:40:18 +0800] [1569] [INFO] Booting worker with pid: 1569
[2025-04-09 08:40:18 +0800] [1570] [INFO] Booting worker with pid: 1570
[2025-04-09 08:40:18 +0800] [1571] [INFO] Booting worker with pid: 1571
[2025-04-09 08:40:18 +0800] [1567] [ERROR] Exception in worker process
Traceback (most recent call last):
  File "/mnt/c/Users/HAng3/Documents/wafer-defect-library/backend/venv/lib/python3.12/site-packages/gunicorn/arbiter.py", line 608, in spawn_worker
    worker.init_process()
  File "/mnt/c/Users/HAng3/Documents/wafer-defect-library/backend/venv/lib/python3.12/site-packages/gunicorn/workers/base.py", line 135, in init_process
    self.load_wsgi()
  File "/mnt/c/Users/HAng3/Documents/wafer-defect-library/backend/venv/lib/python3.12/site-packages/gunicorn/workers/base.py", line 147, in load_wsgi
    self.wsgi = self.app.wsgi()
                ^^^^^^^^^^^^^^^
  File "/mnt/c/Users/HAng3/Documents/wafer-defect-library/backend/venv/lib/python3.12/site-packages/gunicorn/app/base.py", line 66, in wsgi
    self.callable = self.load()
                    ^^^^^^^^^^^
  File "/mnt/c/Users/HAng3/Documents/wafer-defect-library/backend/venv/lib/python3.12/site-packages/gunicorn/app/wsgiapp.py", line 57, in load
    return self.load_wsgiapp()
           ^^^^^^^^^^^^^^^^^^^
  File "/mnt/c/Users/HAng3/Documents/wafer-defect-library/backend/venv/lib/python3.12/site-packages/gunicorn/app/wsgiapp.py", line 47, in load_wsgiapp
    return util.import_app(self.app_uri)
           ^^^^^^^^^^^^^^^^^^^^^^^^^^^^^
  File "/mnt/c/Users/HAng3/Documents/wafer-defect-library/backend/venv/lib/python3.12/site-packages/gunicorn/util.py", line 370, in import_app
    mod = importlib.import_module(module)
          ^^^^^^^^^^^^^^^^^^^^^^^^^^^^^^^
  File "/usr/lib/python3.12/importlib/__init__.py", line 90, in import_module
    return _bootstrap._gcd_import(name[level:], package, level)
           ^^^^^^^^^^^^^^^^^^^^^^^^^^^^^^^^^^^^^^^^^^^^^^^^^^^^
  File "<frozen importlib._bootstrap>", line 1387, in _gcd_import
  File "<frozen importlib._bootstrap>", line 1360, in _find_and_load
  File "<frozen importlib._bootstrap>", line 1324, in _find_and_load_unlocked
ModuleNotFoundError: No module named 'MODULE_NAME'
[2025-04-09 08:40:18 +0800] [1568] [ERROR] Exception in worker process
Traceback (most recent call last):
  File "/mnt/c/Users/HAng3/Documents/wafer-defect-library/backend/venv/lib/python3.12/site-packages/gunicorn/arbiter.py", line 608, in spawn_worker
    worker.init_process()
  File "/mnt/c/Users/HAng3/Documents/wafer-defect-library/backend/venv/lib/python3.12/site-packages/gunicorn/workers/base.py", line 135, in init_process
    self.load_wsgi()
  File "/mnt/c/Users/HAng3/Documents/wafer-defect-library/backend/venv/lib/python3.12/site-packages/gunicorn/workers/base.py", line 147, in load_wsgi
    self.wsgi = self.app.wsgi()
                ^^^^^^^^^^^^^^^
  File "/mnt/c/Users/HAng3/Documents/wafer-defect-library/backend/venv/lib/python3.12/site-packages/gunicorn/app/base.py", line 66, in wsgi
    self.callable = self.load()
                    ^^^^^^^^^^^
  File "/mnt/c/Users/HAng3/Documents/wafer-defect-library/backend/venv/lib/python3.12/site-packages/gunicorn/app/wsgiapp.py", line 57, in load
    return self.load_wsgiapp()
           ^^^^^^^^^^^^^^^^^^^
  File "/mnt/c/Users/HAng3/Documents/wafer-defect-library/backend/venv/lib/python3.12/site-packages/gunicorn/app/wsgiapp.py", line 47, in load_wsgiapp
    return util.import_app(self.app_uri)
           ^^^^^^^^^^^^^^^^^^^^^^^^^^^^^
  File "/mnt/c/Users/HAng3/Documents/wafer-defect-library/backend/venv/lib/python3.12/site-packages/gunicorn/util.py", line 370, in import_app
    mod = importlib.import_module(module)
          ^^^^^^^^^^^^^^^^^^^^^^^^^^^^^^^
  File "/usr/lib/python3.12/importlib/__init__.py", line 90, in import_module
    return _bootstrap._gcd_import(name[level:], package, level)
           ^^^^^^^^^^^^^^^^^^^^^^^^^^^^^^^^^^^^^^^^^^^^^^^^^^^^
  File "<frozen importlib._bootstrap>", line 1387, in _gcd_import
  File "<frozen importlib._bootstrap>", line 1360, in _find_and_load
  File "<frozen importlib._bootstrap>", line 1324, in _find_and_load_unlocked
ModuleNotFoundError: No module named 'MODULE_NAME'
[2025-04-09 08:40:18 +0800] [1567] [INFO] Worker exiting (pid: 1567)
[2025-04-09 08:40:18 +0800] [1568] [INFO] Worker exiting (pid: 1568)
[2025-04-09 08:40:18 +0800] [1569] [ERROR] Exception in worker process
Traceback (most recent call last):
  File "/mnt/c/Users/HAng3/Documents/wafer-defect-library/backend/venv/lib/python3.12/site-packages/gunicorn/arbiter.py", line 608, in spawn_worker
    worker.init_process()
  File "/mnt/c/Users/HAng3/Documents/wafer-defect-library/backend/venv/lib/python3.12/site-packages/gunicorn/workers/base.py", line 135, in init_process
    self.load_wsgi()
  File "/mnt/c/Users/HAng3/Documents/wafer-defect-library/backend/venv/lib/python3.12/site-packages/gunicorn/workers/base.py", line 147, in load_wsgi
    self.wsgi = self.app.wsgi()
                ^^^^^^^^^^^^^^^
  File "/mnt/c/Users/HAng3/Documents/wafer-defect-library/backend/venv/lib/python3.12/site-packages/gunicorn/app/base.py", line 66, in wsgi
    self.callable = self.load()
                    ^^^^^^^^^^^
  File "/mnt/c/Users/HAng3/Documents/wafer-defect-library/backend/venv/lib/python3.12/site-packages/gunicorn/app/wsgiapp.py", line 57, in load
    return self.load_wsgiapp()
           ^^^^^^^^^^^^^^^^^^^
  File "/mnt/c/Users/HAng3/Documents/wafer-defect-library/backend/venv/lib/python3.12/site-packages/gunicorn/app/wsgiapp.py", line 47, in load_wsgiapp
    return util.import_app(self.app_uri)
           ^^^^^^^^^^^^^^^^^^^^^^^^^^^^^
  File "/mnt/c/Users/HAng3/Documents/wafer-defect-library/backend/venv/lib/python3.12/site-packages/gunicorn/util.py", line 370, in import_app
    mod = importlib.import_module(module)
          ^^^^^^^^^^^^^^^^^^^^^^^^^^^^^^^
  File "/usr/lib/python3.12/importlib/__init__.py", line 90, in import_module
    return _bootstrap._gcd_import(name[level:], package, level)
           ^^^^^^^^^^^^^^^^^^^^^^^^^^^^^^^^^^^^^^^^^^^^^^^^^^^^
  File "<frozen importlib._bootstrap>", line 1387, in _gcd_import
  File "<frozen importlib._bootstrap>", line 1360, in _find_and_load
  File "<frozen importlib._bootstrap>", line 1324, in _find_and_load_unlocked
ModuleNotFoundError: No module named 'MODULE_NAME'
[2025-04-09 08:40:18 +0800] [1572] [INFO] Booting worker with pid: 1572
[2025-04-09 08:40:18 +0800] [1569] [INFO] Worker exiting (pid: 1569)
[2025-04-09 08:40:19 +0800] [1566] [ERROR] Worker (pid:1567) exited with code 3
[2025-04-09 08:40:19 +0800] [1566] [ERROR] Worker (pid:1568) was sent SIGTERM!
[2025-04-09 08:40:19 +0800] [1566] [ERROR] Worker (pid:1569) was sent SIGTERM!
[2025-04-09 08:40:18 +0800] [1570] [ERROR] Exception in worker process
Traceback (most recent call last):
  File "/mnt/c/Users/HAng3/Documents/wafer-defect-library/backend/venv/lib/python3.12/site-packages/gunicorn/arbiter.py", line 608, in spawn_worker
    worker.init_process()
  File "/mnt/c/Users/HAng3/Documents/wafer-defect-library/backend/venv/lib/python3.12/site-packages/gunicorn/workers/base.py", line 135, in init_process
    self.load_wsgi()
  File "/mnt/c/Users/HAng3/Documents/wafer-defect-library/backend/venv/lib/python3.12/site-packages/gunicorn/workers/base.py", line 147, in load_wsgi
    self.wsgi = self.app.wsgi()
                ^^^^^^^^^^^^^^^
  File "/mnt/c/Users/HAng3/Documents/wafer-defect-library/backend/venv/lib/python3.12/site-packages/gunicorn/app/base.py", line 66, in wsgi
    self.callable = self.load()
                    ^^^^^^^^^^^
  File "/mnt/c/Users/HAng3/Documents/wafer-defect-library/backend/venv/lib/python3.12/site-packages/gunicorn/app/wsgiapp.py", line 57, in load
    return self.load_wsgiapp()
           ^^^^^^^^^^^^^^^^^^^
  File "/mnt/c/Users/HAng3/Documents/wafer-defect-library/backend/venv/lib/python3.12/site-packages/gunicorn/app/wsgiapp.py", line 47, in load_wsgiapp
    return util.import_app(self.app_uri)
           ^^^^^^^^^^^^^^^^^^^^^^^^^^^^^
  File "/mnt/c/Users/HAng3/Documents/wafer-defect-library/backend/venv/lib/python3.12/site-packages/gunicorn/util.py", line 370, in import_app
    mod = importlib.import_module(module)
          ^^^^^^^^^^^^^^^^^^^^^^^^^^^^^^^
  File "/usr/lib/python3.12/importlib/__init__.py", line 90, in import_module
    return _bootstrap._gcd_import(name[level:], package, level)
           ^^^^^^^^^^^^^^^^^^^^^^^^^^^^^^^^^^^^^^^^^^^^^^^^^^^^
  File "<frozen importlib._bootstrap>", line 1387, in _gcd_import
  File "<frozen importlib._bootstrap>", line 1360, in _find_and_load
  File "<frozen importlib._bootstrap>", line 1324, in _find_and_load_unlocked
ModuleNotFoundError: No module named 'MODULE_NAME'
[2025-04-09 08:40:19 +0800] [1570] [INFO] Worker exiting (pid: 1570)
[2025-04-09 08:40:18 +0800] [1571] [ERROR] Exception in worker process
Traceback (most recent call last):
  File "/mnt/c/Users/HAng3/Documents/wafer-defect-library/backend/venv/lib/python3.12/site-packages/gunicorn/arbiter.py", line 608, in spawn_worker
    worker.init_process()
  File "/mnt/c/Users/HAng3/Documents/wafer-defect-library/backend/venv/lib/python3.12/site-packages/gunicorn/workers/base.py", line 135, in init_process
    self.load_wsgi()
  File "/mnt/c/Users/HAng3/Documents/wafer-defect-library/backend/venv/lib/python3.12/site-packages/gunicorn/workers/base.py", line 147, in load_wsgi
    self.wsgi = self.app.wsgi()
                ^^^^^^^^^^^^^^^
  File "/mnt/c/Users/HAng3/Documents/wafer-defect-library/backend/venv/lib/python3.12/site-packages/gunicorn/app/base.py", line 66, in wsgi
    self.callable = self.load()
                    ^^^^^^^^^^^
  File "/mnt/c/Users/HAng3/Documents/wafer-defect-library/backend/venv/lib/python3.12/site-packages/gunicorn/app/wsgiapp.py", line 57, in load
    return self.load_wsgiapp()
           ^^^^^^^^^^^^^^^^^^^
  File "/mnt/c/Users/HAng3/Documents/wafer-defect-library/backend/venv/lib/python3.12/site-packages/gunicorn/app/wsgiapp.py", line 47, in load_wsgiapp
    return util.import_app(self.app_uri)
           ^^^^^^^^^^^^^^^^^^^^^^^^^^^^^
  File "/mnt/c/Users/HAng3/Documents/wafer-defect-library/backend/venv/lib/python3.12/site-packages/gunicorn/util.py", line 370, in import_app
    mod = importlib.import_module(module)
          ^^^^^^^^^^^^^^^^^^^^^^^^^^^^^^^
  File "/usr/lib/python3.12/importlib/__init__.py", line 90, in import_module
    return _bootstrap._gcd_import(name[level:], package, level)
           ^^^^^^^^^^^^^^^^^^^^^^^^^^^^^^^^^^^^^^^^^^^^^^^^^^^^
  File "<frozen importlib._bootstrap>", line 1387, in _gcd_import
  File "<frozen importlib._bootstrap>", line 1360, in _find_and_load
  File "<frozen importlib._bootstrap>", line 1324, in _find_and_load_unlocked
ModuleNotFoundError: No module named 'MODULE_NAME'
[2025-04-09 08:40:19 +0800] [1571] [INFO] Worker exiting (pid: 1571)
[2025-04-09 08:40:19 +0800] [1566] [ERROR] Worker (pid:1570) exited with code 3
[2025-04-09 08:40:19 +0800] [1566] [ERROR] Worker (pid:1571) exited with code 3
[2025-04-09 08:40:18 +0800] [1572] [ERROR] Exception in worker process
Traceback (most recent call last):
  File "/mnt/c/Users/HAng3/Documents/wafer-defect-library/backend/venv/lib/python3.12/site-packages/gunicorn/arbiter.py", line 608, in spawn_worker
    worker.init_process()
  File "/mnt/c/Users/HAng3/Documents/wafer-defect-library/backend/venv/lib/python3.12/site-packages/gunicorn/workers/base.py", line 135, in init_process
    self.load_wsgi()
  File "/mnt/c/Users/HAng3/Documents/wafer-defect-library/backend/venv/lib/python3.12/site-packages/gunicorn/workers/base.py", line 147, in load_wsgi
    self.wsgi = self.app.wsgi()
                ^^^^^^^^^^^^^^^
  File "/mnt/c/Users/HAng3/Documents/wafer-defect-library/backend/venv/lib/python3.12/site-packages/gunicorn/app/base.py", line 66, in wsgi
    self.callable = self.load()
                    ^^^^^^^^^^^
  File "/mnt/c/Users/HAng3/Documents/wafer-defect-library/backend/venv/lib/python3.12/site-packages/gunicorn/app/wsgiapp.py", line 57, in load
    return self.load_wsgiapp()
           ^^^^^^^^^^^^^^^^^^^
  File "/mnt/c/Users/HAng3/Documents/wafer-defect-library/backend/venv/lib/python3.12/site-packages/gunicorn/app/wsgiapp.py", line 47, in load_wsgiapp
    return util.import_app(self.app_uri)
           ^^^^^^^^^^^^^^^^^^^^^^^^^^^^^
  File "/mnt/c/Users/HAng3/Documents/wafer-defect-library/backend/venv/lib/python3.12/site-packages/gunicorn/util.py", line 370, in import_app
    mod = importlib.import_module(module)
          ^^^^^^^^^^^^^^^^^^^^^^^^^^^^^^^
  File "/usr/lib/python3.12/importlib/__init__.py", line 90, in import_module
    return _bootstrap._gcd_import(name[level:], package, level)
           ^^^^^^^^^^^^^^^^^^^^^^^^^^^^^^^^^^^^^^^^^^^^^^^^^^^^
  File "<frozen importlib._bootstrap>", line 1387, in _gcd_import
  File "<frozen importlib._bootstrap>", line 1360, in _find_and_load
  File "<frozen importlib._bootstrap>", line 1324, in _find_and_load_unlocked
ModuleNotFoundError: No module named 'MODULE_NAME'
[2025-04-09 08:40:19 +0800] [1572] [INFO] Worker exiting (pid: 1572)
[2025-04-09 08:40:19 +0800] [1566] [ERROR] Worker (pid:1572) exited with code 3
[2025-04-09 08:41:55 +0800] [1576] [INFO] Starting gunicorn 23.0.0
[2025-04-09 08:41:55 +0800] [1576] [INFO] Listening at: http://127.0.0.1:8000 (1576)
[2025-04-09 08:41:55 +0800] [1576] [INFO] Using worker: sync
[2025-04-09 08:41:55 +0800] [1577] [INFO] Booting worker with pid: 1577
[2025-04-09 08:41:55 +0800] [1578] [INFO] Booting worker with pid: 1578
[2025-04-09 08:41:55 +0800] [1579] [INFO] Booting worker with pid: 1579
[2025-04-09 08:41:55 +0800] [1578] [ERROR] Exception in worker process
Traceback (most recent call last):
  File "/mnt/c/Users/HAng3/Documents/wafer-defect-library/backend/venv/lib/python3.12/site-packages/gunicorn/arbiter.py", line 608, in spawn_worker
    worker.init_process()
  File "/mnt/c/Users/HAng3/Documents/wafer-defect-library/backend/venv/lib/python3.12/site-packages/gunicorn/workers/base.py", line 135, in init_process
    self.load_wsgi()
  File "/mnt/c/Users/HAng3/Documents/wafer-defect-library/backend/venv/lib/python3.12/site-packages/gunicorn/workers/base.py", line 147, in load_wsgi
    self.wsgi = self.app.wsgi()
                ^^^^^^^^^^^^^^^
  File "/mnt/c/Users/HAng3/Documents/wafer-defect-library/backend/venv/lib/python3.12/site-packages/gunicorn/app/base.py", line 66, in wsgi
    self.callable = self.load()
                    ^^^^^^^^^^^
  File "/mnt/c/Users/HAng3/Documents/wafer-defect-library/backend/venv/lib/python3.12/site-packages/gunicorn/app/wsgiapp.py", line 57, in load
    return self.load_wsgiapp()
           ^^^^^^^^^^^^^^^^^^^
  File "/mnt/c/Users/HAng3/Documents/wafer-defect-library/backend/venv/lib/python3.12/site-packages/gunicorn/app/wsgiapp.py", line 47, in load_wsgiapp
    return util.import_app(self.app_uri)
           ^^^^^^^^^^^^^^^^^^^^^^^^^^^^^
  File "/mnt/c/Users/HAng3/Documents/wafer-defect-library/backend/venv/lib/python3.12/site-packages/gunicorn/util.py", line 370, in import_app
    mod = importlib.import_module(module)
          ^^^^^^^^^^^^^^^^^^^^^^^^^^^^^^^
  File "/usr/lib/python3.12/importlib/__init__.py", line 90, in import_module
    return _bootstrap._gcd_import(name[level:], package, level)
           ^^^^^^^^^^^^^^^^^^^^^^^^^^^^^^^^^^^^^^^^^^^^^^^^^^^^
  File "<frozen importlib._bootstrap>", line 1387, in _gcd_import
  File "<frozen importlib._bootstrap>", line 1360, in _find_and_load
  File "<frozen importlib._bootstrap>", line 1324, in _find_and_load_unlocked
ModuleNotFoundError: No module named 'MODULE_NAME'
[2025-04-09 08:41:55 +0800] [1578] [INFO] Worker exiting (pid: 1578)
[2025-04-09 08:41:55 +0800] [1577] [ERROR] Exception in worker process
Traceback (most recent call last):
  File "/mnt/c/Users/HAng3/Documents/wafer-defect-library/backend/venv/lib/python3.12/site-packages/gunicorn/arbiter.py", line 608, in spawn_worker
    worker.init_process()
  File "/mnt/c/Users/HAng3/Documents/wafer-defect-library/backend/venv/lib/python3.12/site-packages/gunicorn/workers/base.py", line 135, in init_process
    self.load_wsgi()
  File "/mnt/c/Users/HAng3/Documents/wafer-defect-library/backend/venv/lib/python3.12/site-packages/gunicorn/workers/base.py", line 147, in load_wsgi
    self.wsgi = self.app.wsgi()
                ^^^^^^^^^^^^^^^
  File "/mnt/c/Users/HAng3/Documents/wafer-defect-library/backend/venv/lib/python3.12/site-packages/gunicorn/app/base.py", line 66, in wsgi
    self.callable = self.load()
                    ^^^^^^^^^^^
  File "/mnt/c/Users/HAng3/Documents/wafer-defect-library/backend/venv/lib/python3.12/site-packages/gunicorn/app/wsgiapp.py", line 57, in load
    return self.load_wsgiapp()
           ^^^^^^^^^^^^^^^^^^^
  File "/mnt/c/Users/HAng3/Documents/wafer-defect-library/backend/venv/lib/python3.12/site-packages/gunicorn/app/wsgiapp.py", line 47, in load_wsgiapp
    return util.import_app(self.app_uri)
           ^^^^^^^^^^^^^^^^^^^^^^^^^^^^^
  File "/mnt/c/Users/HAng3/Documents/wafer-defect-library/backend/venv/lib/python3.12/site-packages/gunicorn/util.py", line 370, in import_app
    mod = importlib.import_module(module)
          ^^^^^^^^^^^^^^^^^^^^^^^^^^^^^^^
  File "/usr/lib/python3.12/importlib/__init__.py", line 90, in import_module
    return _bootstrap._gcd_import(name[level:], package, level)
           ^^^^^^^^^^^^^^^^^^^^^^^^^^^^^^^^^^^^^^^^^^^^^^^^^^^^
  File "<frozen importlib._bootstrap>", line 1387, in _gcd_import
  File "<frozen importlib._bootstrap>", line 1360, in _find_and_load
  File "<frozen importlib._bootstrap>", line 1324, in _find_and_load_unlocked
ModuleNotFoundError: No module named 'MODULE_NAME'
[2025-04-09 08:41:55 +0800] [1577] [INFO] Worker exiting (pid: 1577)
[2025-04-09 08:41:55 +0800] [1576] [ERROR] Worker (pid:1578) exited with code 3
[2025-04-09 08:41:55 +0800] [1576] [ERROR] Worker (pid:1577) was sent SIGTERM!
[2025-04-09 08:41:55 +0800] [1579] [ERROR] Exception in worker process
Traceback (most recent call last):
  File "/mnt/c/Users/HAng3/Documents/wafer-defect-library/backend/venv/lib/python3.12/site-packages/gunicorn/arbiter.py", line 608, in spawn_worker
    worker.init_process()
  File "/mnt/c/Users/HAng3/Documents/wafer-defect-library/backend/venv/lib/python3.12/site-packages/gunicorn/workers/base.py", line 135, in init_process
    self.load_wsgi()
  File "/mnt/c/Users/HAng3/Documents/wafer-defect-library/backend/venv/lib/python3.12/site-packages/gunicorn/workers/base.py", line 147, in load_wsgi
    self.wsgi = self.app.wsgi()
                ^^^^^^^^^^^^^^^
  File "/mnt/c/Users/HAng3/Documents/wafer-defect-library/backend/venv/lib/python3.12/site-packages/gunicorn/app/base.py", line 66, in wsgi
    self.callable = self.load()
                    ^^^^^^^^^^^
  File "/mnt/c/Users/HAng3/Documents/wafer-defect-library/backend/venv/lib/python3.12/site-packages/gunicorn/app/wsgiapp.py", line 57, in load
    return self.load_wsgiapp()
           ^^^^^^^^^^^^^^^^^^^
  File "/mnt/c/Users/HAng3/Documents/wafer-defect-library/backend/venv/lib/python3.12/site-packages/gunicorn/app/wsgiapp.py", line 47, in load_wsgiapp
    return util.import_app(self.app_uri)
           ^^^^^^^^^^^^^^^^^^^^^^^^^^^^^
  File "/mnt/c/Users/HAng3/Documents/wafer-defect-library/backend/venv/lib/python3.12/site-packages/gunicorn/util.py", line 370, in import_app
    mod = importlib.import_module(module)
          ^^^^^^^^^^^^^^^^^^^^^^^^^^^^^^^
  File "/usr/lib/python3.12/importlib/__init__.py", line 90, in import_module
    return _bootstrap._gcd_import(name[level:], package, level)
           ^^^^^^^^^^^^^^^^^^^^^^^^^^^^^^^^^^^^^^^^^^^^^^^^^^^^
  File "<frozen importlib._bootstrap>", line 1387, in _gcd_import
  File "<frozen importlib._bootstrap>", line 1360, in _find_and_load
  File "<frozen importlib._bootstrap>", line 1324, in _find_and_load_unlocked
ModuleNotFoundError: No module named 'MODULE_NAME'
[2025-04-09 08:41:55 +0800] [1579] [INFO] Worker exiting (pid: 1579)
[2025-04-09 08:41:55 +0800] [1576] [ERROR] Worker (pid:1579) exited with code 3
[2025-04-09 08:42:49 +0800] [1601] [INFO] Starting gunicorn 23.0.0
[2025-04-09 08:42:49 +0800] [1601] [INFO] Listening at: http://127.0.0.1:8000 (1601)
[2025-04-09 08:42:49 +0800] [1601] [INFO] Using worker: sync
[2025-04-09 08:42:49 +0800] [1602] [INFO] Booting worker with pid: 1602
[2025-04-09 08:42:50 +0800] [1603] [INFO] Booting worker with pid: 1603
[2025-04-09 08:42:50 +0800] [1604] [INFO] Booting worker with pid: 1604
[2025-04-09 08:42:50 +0800] [1605] [INFO] Booting worker with pid: 1605
[2025-04-09 08:42:50 +0800] [1606] [INFO] Booting worker with pid: 1606
[2025-04-09 08:42:50 +0800] [1607] [INFO] Booting worker with pid: 1607
[2025-04-09 08:42:50 +0800] [1608] [INFO] Booting worker with pid: 1608
[2025-04-09 08:42:50 +0800] [1609] [INFO] Booting worker with pid: 1609
[2025-04-09 08:42:50 +0800] [1610] [INFO] Booting worker with pid: 1610
[2025-04-09 08:42:50 +0800] [1611] [INFO] Booting worker with pid: 1611
[2025-04-09 08:42:50 +0800] [1612] [INFO] Booting worker with pid: 1612
[2025-04-09 08:42:50 +0800] [1613] [INFO] Booting worker with pid: 1613
[2025-04-09 08:42:50 +0800] [1614] [INFO] Booting worker with pid: 1614
[2025-04-09 08:42:50 +0800] [1615] [INFO] Booting worker with pid: 1615
[2025-04-09 08:42:50 +0800] [1616] [INFO] Booting worker with pid: 1616
[2025-04-09 08:42:50 +0800] [1617] [INFO] Booting worker with pid: 1617
[2025-04-09 08:42:50 +0800] [1618] [INFO] Booting worker with pid: 1618
[2025-04-09 08:43:20 +0800] [1612] [ERROR] Exception in worker process
Traceback (most recent call last):
  File "/mnt/c/Users/HAng3/Documents/wafer-defect-library/backend/venv/lib/python3.12/site-packages/gunicorn/arbiter.py", line 608, in spawn_worker
    worker.init_process()
  File "/mnt/c/Users/HAng3/Documents/wafer-defect-library/backend/venv/lib/python3.12/site-packages/gunicorn/workers/base.py", line 135, in init_process
    self.load_wsgi()
  File "/mnt/c/Users/HAng3/Documents/wafer-defect-library/backend/venv/lib/python3.12/site-packages/gunicorn/workers/base.py", line 147, in load_wsgi
    self.wsgi = self.app.wsgi()
                ^^^^^^^^^^^^^^^
  File "/mnt/c/Users/HAng3/Documents/wafer-defect-library/backend/venv/lib/python3.12/site-packages/gunicorn/app/base.py", line 66, in wsgi
    self.callable = self.load()
                    ^^^^^^^^^^^
  File "/mnt/c/Users/HAng3/Documents/wafer-defect-library/backend/venv/lib/python3.12/site-packages/gunicorn/app/wsgiapp.py", line 57, in load
    return self.load_wsgiapp()
           ^^^^^^^^^^^^^^^^^^^
  File "/mnt/c/Users/HAng3/Documents/wafer-defect-library/backend/venv/lib/python3.12/site-packages/gunicorn/app/wsgiapp.py", line 47, in load_wsgiapp
    return util.import_app(self.app_uri)
           ^^^^^^^^^^^^^^^^^^^^^^^^^^^^^
  File "/mnt/c/Users/HAng3/Documents/wafer-defect-library/backend/venv/lib/python3.12/site-packages/gunicorn/util.py", line 370, in import_app
    mod = importlib.import_module(module)
          ^^^^^^^^^^^^^^^^^^^^^^^^^^^^^^^
  File "/usr/lib/python3.12/importlib/__init__.py", line 90, in import_module
    return _bootstrap._gcd_import(name[level:], package, level)
           ^^^^^^^^^^^^^^^^^^^^^^^^^^^^^^^^^^^^^^^^^^^^^^^^^^^^
  File "<frozen importlib._bootstrap>", line 1387, in _gcd_import
  File "<frozen importlib._bootstrap>", line 1360, in _find_and_load
  File "<frozen importlib._bootstrap>", line 1331, in _find_and_load_unlocked
  File "<frozen importlib._bootstrap>", line 935, in _load_unlocked
  File "<frozen importlib._bootstrap_external>", line 995, in exec_module
  File "<frozen importlib._bootstrap>", line 488, in _call_with_frames_removed
  File "/mnt/c/Users/HAng3/Documents/wafer-defect-library/backend/app.py", line 5, in <module>
    from flask_cors import CORS
ModuleNotFoundError: No module named 'flask_cors'
[2025-04-09 08:43:20 +0800] [1603] [ERROR] Exception in worker process
Traceback (most recent call last):
  File "/mnt/c/Users/HAng3/Documents/wafer-defect-library/backend/venv/lib/python3.12/site-packages/gunicorn/arbiter.py", line 608, in spawn_worker
    worker.init_process()
  File "/mnt/c/Users/HAng3/Documents/wafer-defect-library/backend/venv/lib/python3.12/site-packages/gunicorn/workers/base.py", line 135, in init_process
    self.load_wsgi()
  File "/mnt/c/Users/HAng3/Documents/wafer-defect-library/backend/venv/lib/python3.12/site-packages/gunicorn/workers/base.py", line 147, in load_wsgi
    self.wsgi = self.app.wsgi()
                ^^^^^^^^^^^^^^^
  File "/mnt/c/Users/HAng3/Documents/wafer-defect-library/backend/venv/lib/python3.12/site-packages/gunicorn/app/base.py", line 66, in wsgi
    self.callable = self.load()
                    ^^^^^^^^^^^
  File "/mnt/c/Users/HAng3/Documents/wafer-defect-library/backend/venv/lib/python3.12/site-packages/gunicorn/app/wsgiapp.py", line 57, in load
    return self.load_wsgiapp()
           ^^^^^^^^^^^^^^^^^^^
  File "/mnt/c/Users/HAng3/Documents/wafer-defect-library/backend/venv/lib/python3.12/site-packages/gunicorn/app/wsgiapp.py", line 47, in load_wsgiapp
    return util.import_app(self.app_uri)
           ^^^^^^^^^^^^^^^^^^^^^^^^^^^^^
  File "/mnt/c/Users/HAng3/Documents/wafer-defect-library/backend/venv/lib/python3.12/site-packages/gunicorn/util.py", line 370, in import_app
    mod = importlib.import_module(module)
          ^^^^^^^^^^^^^^^^^^^^^^^^^^^^^^^
  File "/usr/lib/python3.12/importlib/__init__.py", line 90, in import_module
    return _bootstrap._gcd_import(name[level:], package, level)
           ^^^^^^^^^^^^^^^^^^^^^^^^^^^^^^^^^^^^^^^^^^^^^^^^^^^^
  File "<frozen importlib._bootstrap>", line 1387, in _gcd_import
  File "<frozen importlib._bootstrap>", line 1360, in _find_and_load
  File "<frozen importlib._bootstrap>", line 1331, in _find_and_load_unlocked
  File "<frozen importlib._bootstrap>", line 935, in _load_unlocked
  File "<frozen importlib._bootstrap_external>", line 995, in exec_module
  File "<frozen importlib._bootstrap>", line 488, in _call_with_frames_removed
  File "/mnt/c/Users/HAng3/Documents/wafer-defect-library/backend/app.py", line 5, in <module>
    from flask_cors import CORS
ModuleNotFoundError: No module named 'flask_cors'
[2025-04-09 08:43:20 +0800] [1605] [ERROR] Exception in worker process
Traceback (most recent call last):
  File "/mnt/c/Users/HAng3/Documents/wafer-defect-library/backend/venv/lib/python3.12/site-packages/gunicorn/arbiter.py", line 608, in spawn_worker
    worker.init_process()
  File "/mnt/c/Users/HAng3/Documents/wafer-defect-library/backend/venv/lib/python3.12/site-packages/gunicorn/workers/base.py", line 135, in init_process
    self.load_wsgi()
  File "/mnt/c/Users/HAng3/Documents/wafer-defect-library/backend/venv/lib/python3.12/site-packages/gunicorn/workers/base.py", line 147, in load_wsgi
    self.wsgi = self.app.wsgi()
                ^^^^^^^^^^^^^^^
  File "/mnt/c/Users/HAng3/Documents/wafer-defect-library/backend/venv/lib/python3.12/site-packages/gunicorn/app/base.py", line 66, in wsgi
    self.callable = self.load()
                    ^^^^^^^^^^^
  File "/mnt/c/Users/HAng3/Documents/wafer-defect-library/backend/venv/lib/python3.12/site-packages/gunicorn/app/wsgiapp.py", line 57, in load
    return self.load_wsgiapp()
           ^^^^^^^^^^^^^^^^^^^
  File "/mnt/c/Users/HAng3/Documents/wafer-defect-library/backend/venv/lib/python3.12/site-packages/gunicorn/app/wsgiapp.py", line 47, in load_wsgiapp
    return util.import_app(self.app_uri)
           ^^^^^^^^^^^^^^^^^^^^^^^^^^^^^
  File "/mnt/c/Users/HAng3/Documents/wafer-defect-library/backend/venv/lib/python3.12/site-packages/gunicorn/util.py", line 370, in import_app
    mod = importlib.import_module(module)
          ^^^^^^^^^^^^^^^^^^^^^^^^^^^^^^^
  File "/usr/lib/python3.12/importlib/__init__.py", line 90, in import_module
    return _bootstrap._gcd_import(name[level:], package, level)
           ^^^^^^^^^^^^^^^^^^^^^^^^^^^^^^^^^^^^^^^^^^^^^^^^^^^^
  File "<frozen importlib._bootstrap>", line 1387, in _gcd_import
  File "<frozen importlib._bootstrap>", line 1360, in _find_and_load
  File "<frozen importlib._bootstrap>", line 1331, in _find_and_load_unlocked
  File "<frozen importlib._bootstrap>", line 935, in _load_unlocked
  File "<frozen importlib._bootstrap_external>", line 995, in exec_module
  File "<frozen importlib._bootstrap>", line 488, in _call_with_frames_removed
  File "/mnt/c/Users/HAng3/Documents/wafer-defect-library/backend/app.py", line 5, in <module>
    from flask_cors import CORS
ModuleNotFoundError: No module named 'flask_cors'
[2025-04-09 08:43:20 +0800] [1602] [ERROR] Exception in worker process
Traceback (most recent call last):
  File "/mnt/c/Users/HAng3/Documents/wafer-defect-library/backend/venv/lib/python3.12/site-packages/gunicorn/arbiter.py", line 608, in spawn_worker
    worker.init_process()
  File "/mnt/c/Users/HAng3/Documents/wafer-defect-library/backend/venv/lib/python3.12/site-packages/gunicorn/workers/base.py", line 135, in init_process
    self.load_wsgi()
  File "/mnt/c/Users/HAng3/Documents/wafer-defect-library/backend/venv/lib/python3.12/site-packages/gunicorn/workers/base.py", line 147, in load_wsgi
    self.wsgi = self.app.wsgi()
                ^^^^^^^^^^^^^^^
  File "/mnt/c/Users/HAng3/Documents/wafer-defect-library/backend/venv/lib/python3.12/site-packages/gunicorn/app/base.py", line 66, in wsgi
    self.callable = self.load()
                    ^^^^^^^^^^^
  File "/mnt/c/Users/HAng3/Documents/wafer-defect-library/backend/venv/lib/python3.12/site-packages/gunicorn/app/wsgiapp.py", line 57, in load
    return self.load_wsgiapp()
           ^^^^^^^^^^^^^^^^^^^
  File "/mnt/c/Users/HAng3/Documents/wafer-defect-library/backend/venv/lib/python3.12/site-packages/gunicorn/app/wsgiapp.py", line 47, in load_wsgiapp
    return util.import_app(self.app_uri)
           ^^^^^^^^^^^^^^^^^^^^^^^^^^^^^
  File "/mnt/c/Users/HAng3/Documents/wafer-defect-library/backend/venv/lib/python3.12/site-packages/gunicorn/util.py", line 370, in import_app
    mod = importlib.import_module(module)
          ^^^^^^^^^^^^^^^^^^^^^^^^^^^^^^^
  File "/usr/lib/python3.12/importlib/__init__.py", line 90, in import_module
    return _bootstrap._gcd_import(name[level:], package, level)
           ^^^^^^^^^^^^^^^^^^^^^^^^^^^^^^^^^^^^^^^^^^^^^^^^^^^^
  File "<frozen importlib._bootstrap>", line 1387, in _gcd_import
  File "<frozen importlib._bootstrap>", line 1360, in _find_and_load
  File "<frozen importlib._bootstrap>", line 1331, in _find_and_load_unlocked
  File "<frozen importlib._bootstrap>", line 935, in _load_unlocked
  File "<frozen importlib._bootstrap_external>", line 995, in exec_module
  File "<frozen importlib._bootstrap>", line 488, in _call_with_frames_removed
  File "/mnt/c/Users/HAng3/Documents/wafer-defect-library/backend/app.py", line 5, in <module>
    from flask_cors import CORS
ModuleNotFoundError: No module named 'flask_cors'
[2025-04-09 08:43:20 +0800] [1609] [ERROR] Exception in worker process
Traceback (most recent call last):
  File "/mnt/c/Users/HAng3/Documents/wafer-defect-library/backend/venv/lib/python3.12/site-packages/gunicorn/arbiter.py", line 608, in spawn_worker
    worker.init_process()
  File "/mnt/c/Users/HAng3/Documents/wafer-defect-library/backend/venv/lib/python3.12/site-packages/gunicorn/workers/base.py", line 135, in init_process
    self.load_wsgi()
  File "/mnt/c/Users/HAng3/Documents/wafer-defect-library/backend/venv/lib/python3.12/site-packages/gunicorn/workers/base.py", line 147, in load_wsgi
    self.wsgi = self.app.wsgi()
                ^^^^^^^^^^^^^^^
  File "/mnt/c/Users/HAng3/Documents/wafer-defect-library/backend/venv/lib/python3.12/site-packages/gunicorn/app/base.py", line 66, in wsgi
    self.callable = self.load()
                    ^^^^^^^^^^^
  File "/mnt/c/Users/HAng3/Documents/wafer-defect-library/backend/venv/lib/python3.12/site-packages/gunicorn/app/wsgiapp.py", line 57, in load
    return self.load_wsgiapp()
           ^^^^^^^^^^^^^^^^^^^
  File "/mnt/c/Users/HAng3/Documents/wafer-defect-library/backend/venv/lib/python3.12/site-packages/gunicorn/app/wsgiapp.py", line 47, in load_wsgiapp
    return util.import_app(self.app_uri)
           ^^^^^^^^^^^^^^^^^^^^^^^^^^^^^
  File "/mnt/c/Users/HAng3/Documents/wafer-defect-library/backend/venv/lib/python3.12/site-packages/gunicorn/util.py", line 370, in import_app
    mod = importlib.import_module(module)
          ^^^^^^^^^^^^^^^^^^^^^^^^^^^^^^^
  File "/usr/lib/python3.12/importlib/__init__.py", line 90, in import_module
    return _bootstrap._gcd_import(name[level:], package, level)
           ^^^^^^^^^^^^^^^^^^^^^^^^^^^^^^^^^^^^^^^^^^^^^^^^^^^^
  File "<frozen importlib._bootstrap>", line 1387, in _gcd_import
  File "<frozen importlib._bootstrap>", line 1360, in _find_and_load
  File "<frozen importlib._bootstrap>", line 1331, in _find_and_load_unlocked
  File "<frozen importlib._bootstrap>", line 935, in _load_unlocked
  File "<frozen importlib._bootstrap_external>", line 995, in exec_module
  File "<frozen importlib._bootstrap>", line 488, in _call_with_frames_removed
  File "/mnt/c/Users/HAng3/Documents/wafer-defect-library/backend/app.py", line 5, in <module>
    from flask_cors import CORS
ModuleNotFoundError: No module named 'flask_cors'
[2025-04-09 08:43:21 +0800] [1612] [INFO] Worker exiting (pid: 1612)
[2025-04-09 08:43:20 +0800] [1607] [ERROR] Exception in worker process
Traceback (most recent call last):
  File "/mnt/c/Users/HAng3/Documents/wafer-defect-library/backend/venv/lib/python3.12/site-packages/gunicorn/arbiter.py", line 608, in spawn_worker
    worker.init_process()
  File "/mnt/c/Users/HAng3/Documents/wafer-defect-library/backend/venv/lib/python3.12/site-packages/gunicorn/workers/base.py", line 135, in init_process
    self.load_wsgi()
  File "/mnt/c/Users/HAng3/Documents/wafer-defect-library/backend/venv/lib/python3.12/site-packages/gunicorn/workers/base.py", line 147, in load_wsgi
    self.wsgi = self.app.wsgi()
                ^^^^^^^^^^^^^^^
  File "/mnt/c/Users/HAng3/Documents/wafer-defect-library/backend/venv/lib/python3.12/site-packages/gunicorn/app/base.py", line 66, in wsgi
    self.callable = self.load()
                    ^^^^^^^^^^^
  File "/mnt/c/Users/HAng3/Documents/wafer-defect-library/backend/venv/lib/python3.12/site-packages/gunicorn/app/wsgiapp.py", line 57, in load
    return self.load_wsgiapp()
           ^^^^^^^^^^^^^^^^^^^
  File "/mnt/c/Users/HAng3/Documents/wafer-defect-library/backend/venv/lib/python3.12/site-packages/gunicorn/app/wsgiapp.py", line 47, in load_wsgiapp
    return util.import_app(self.app_uri)
           ^^^^^^^^^^^^^^^^^^^^^^^^^^^^^
  File "/mnt/c/Users/HAng3/Documents/wafer-defect-library/backend/venv/lib/python3.12/site-packages/gunicorn/util.py", line 370, in import_app
    mod = importlib.import_module(module)
          ^^^^^^^^^^^^^^^^^^^^^^^^^^^^^^^
  File "/usr/lib/python3.12/importlib/__init__.py", line 90, in import_module
    return _bootstrap._gcd_import(name[level:], package, level)
           ^^^^^^^^^^^^^^^^^^^^^^^^^^^^^^^^^^^^^^^^^^^^^^^^^^^^
  File "<frozen importlib._bootstrap>", line 1387, in _gcd_import
  File "<frozen importlib._bootstrap>", line 1360, in _find_and_load
  File "<frozen importlib._bootstrap>", line 1331, in _find_and_load_unlocked
  File "<frozen importlib._bootstrap>", line 935, in _load_unlocked
  File "<frozen importlib._bootstrap_external>", line 995, in exec_module
  File "<frozen importlib._bootstrap>", line 488, in _call_with_frames_removed
  File "/mnt/c/Users/HAng3/Documents/wafer-defect-library/backend/app.py", line 5, in <module>
    from flask_cors import CORS
ModuleNotFoundError: No module named 'flask_cors'
[2025-04-09 08:43:21 +0800] [1603] [INFO] Worker exiting (pid: 1603)
[2025-04-09 08:43:21 +0800] [1605] [INFO] Worker exiting (pid: 1605)
[2025-04-09 08:43:21 +0800] [1602] [INFO] Worker exiting (pid: 1602)
[2025-04-09 08:43:21 +0800] [1609] [INFO] Worker exiting (pid: 1609)
[2025-04-09 08:43:21 +0800] [1607] [INFO] Worker exiting (pid: 1607)
[2025-04-09 08:43:21 +0800] [1604] [ERROR] Exception in worker process
Traceback (most recent call last):
  File "/mnt/c/Users/HAng3/Documents/wafer-defect-library/backend/venv/lib/python3.12/site-packages/gunicorn/arbiter.py", line 608, in spawn_worker
    worker.init_process()
  File "/mnt/c/Users/HAng3/Documents/wafer-defect-library/backend/venv/lib/python3.12/site-packages/gunicorn/workers/base.py", line 135, in init_process
    self.load_wsgi()
  File "/mnt/c/Users/HAng3/Documents/wafer-defect-library/backend/venv/lib/python3.12/site-packages/gunicorn/workers/base.py", line 147, in load_wsgi
    self.wsgi = self.app.wsgi()
                ^^^^^^^^^^^^^^^
  File "/mnt/c/Users/HAng3/Documents/wafer-defect-library/backend/venv/lib/python3.12/site-packages/gunicorn/app/base.py", line 66, in wsgi
    self.callable = self.load()
                    ^^^^^^^^^^^
  File "/mnt/c/Users/HAng3/Documents/wafer-defect-library/backend/venv/lib/python3.12/site-packages/gunicorn/app/wsgiapp.py", line 57, in load
    return self.load_wsgiapp()
           ^^^^^^^^^^^^^^^^^^^
  File "/mnt/c/Users/HAng3/Documents/wafer-defect-library/backend/venv/lib/python3.12/site-packages/gunicorn/app/wsgiapp.py", line 47, in load_wsgiapp
    return util.import_app(self.app_uri)
           ^^^^^^^^^^^^^^^^^^^^^^^^^^^^^
  File "/mnt/c/Users/HAng3/Documents/wafer-defect-library/backend/venv/lib/python3.12/site-packages/gunicorn/util.py", line 370, in import_app
    mod = importlib.import_module(module)
          ^^^^^^^^^^^^^^^^^^^^^^^^^^^^^^^
  File "/usr/lib/python3.12/importlib/__init__.py", line 90, in import_module
    return _bootstrap._gcd_import(name[level:], package, level)
           ^^^^^^^^^^^^^^^^^^^^^^^^^^^^^^^^^^^^^^^^^^^^^^^^^^^^
  File "<frozen importlib._bootstrap>", line 1387, in _gcd_import
  File "<frozen importlib._bootstrap>", line 1360, in _find_and_load
  File "<frozen importlib._bootstrap>", line 1331, in _find_and_load_unlocked
  File "<frozen importlib._bootstrap>", line 935, in _load_unlocked
  File "<frozen importlib._bootstrap_external>", line 995, in exec_module
  File "<frozen importlib._bootstrap>", line 488, in _call_with_frames_removed
  File "/mnt/c/Users/HAng3/Documents/wafer-defect-library/backend/app.py", line 5, in <module>
    from flask_cors import CORS
ModuleNotFoundError: No module named 'flask_cors'
[2025-04-09 08:43:21 +0800] [1604] [INFO] Worker exiting (pid: 1604)
[2025-04-09 08:43:21 +0800] [1615] [ERROR] Exception in worker process
Traceback (most recent call last):
  File "/mnt/c/Users/HAng3/Documents/wafer-defect-library/backend/venv/lib/python3.12/site-packages/gunicorn/arbiter.py", line 608, in spawn_worker
    worker.init_process()
  File "/mnt/c/Users/HAng3/Documents/wafer-defect-library/backend/venv/lib/python3.12/site-packages/gunicorn/workers/base.py", line 135, in init_process
    self.load_wsgi()
  File "/mnt/c/Users/HAng3/Documents/wafer-defect-library/backend/venv/lib/python3.12/site-packages/gunicorn/workers/base.py", line 147, in load_wsgi
    self.wsgi = self.app.wsgi()
                ^^^^^^^^^^^^^^^
  File "/mnt/c/Users/HAng3/Documents/wafer-defect-library/backend/venv/lib/python3.12/site-packages/gunicorn/app/base.py", line 66, in wsgi
    self.callable = self.load()
                    ^^^^^^^^^^^
  File "/mnt/c/Users/HAng3/Documents/wafer-defect-library/backend/venv/lib/python3.12/site-packages/gunicorn/app/wsgiapp.py", line 57, in load
    return self.load_wsgiapp()
           ^^^^^^^^^^^^^^^^^^^
  File "/mnt/c/Users/HAng3/Documents/wafer-defect-library/backend/venv/lib/python3.12/site-packages/gunicorn/app/wsgiapp.py", line 47, in load_wsgiapp
    return util.import_app(self.app_uri)
           ^^^^^^^^^^^^^^^^^^^^^^^^^^^^^
  File "/mnt/c/Users/HAng3/Documents/wafer-defect-library/backend/venv/lib/python3.12/site-packages/gunicorn/util.py", line 370, in import_app
    mod = importlib.import_module(module)
          ^^^^^^^^^^^^^^^^^^^^^^^^^^^^^^^
  File "/usr/lib/python3.12/importlib/__init__.py", line 90, in import_module
    return _bootstrap._gcd_import(name[level:], package, level)
           ^^^^^^^^^^^^^^^^^^^^^^^^^^^^^^^^^^^^^^^^^^^^^^^^^^^^
  File "<frozen importlib._bootstrap>", line 1387, in _gcd_import
  File "<frozen importlib._bootstrap>", line 1360, in _find_and_load
  File "<frozen importlib._bootstrap>", line 1331, in _find_and_load_unlocked
  File "<frozen importlib._bootstrap>", line 935, in _load_unlocked
  File "<frozen importlib._bootstrap_external>", line 995, in exec_module
  File "<frozen importlib._bootstrap>", line 488, in _call_with_frames_removed
  File "/mnt/c/Users/HAng3/Documents/wafer-defect-library/backend/app.py", line 5, in <module>
    from flask_cors import CORS
ModuleNotFoundError: No module named 'flask_cors'
[2025-04-09 08:43:21 +0800] [1615] [INFO] Worker exiting (pid: 1615)
[2025-04-09 08:43:21 +0800] [1601] [ERROR] Worker (pid:1602) exited with code 3
[2025-04-09 08:43:21 +0800] [1601] [ERROR] Worker (pid:1603) exited with code 3
[2025-04-09 08:43:21 +0800] [1601] [ERROR] Worker (pid:1605) exited with code 3
[2025-04-09 08:43:21 +0800] [1613] [ERROR] Exception in worker process
Traceback (most recent call last):
  File "/mnt/c/Users/HAng3/Documents/wafer-defect-library/backend/venv/lib/python3.12/site-packages/gunicorn/arbiter.py", line 608, in spawn_worker
    worker.init_process()
  File "/mnt/c/Users/HAng3/Documents/wafer-defect-library/backend/venv/lib/python3.12/site-packages/gunicorn/workers/base.py", line 135, in init_process
    self.load_wsgi()
  File "/mnt/c/Users/HAng3/Documents/wafer-defect-library/backend/venv/lib/python3.12/site-packages/gunicorn/workers/base.py", line 147, in load_wsgi
    self.wsgi = self.app.wsgi()
                ^^^^^^^^^^^^^^^
  File "/mnt/c/Users/HAng3/Documents/wafer-defect-library/backend/venv/lib/python3.12/site-packages/gunicorn/app/base.py", line 66, in wsgi
    self.callable = self.load()
                    ^^^^^^^^^^^
  File "/mnt/c/Users/HAng3/Documents/wafer-defect-library/backend/venv/lib/python3.12/site-packages/gunicorn/app/wsgiapp.py", line 57, in load
    return self.load_wsgiapp()
           ^^^^^^^^^^^^^^^^^^^
  File "/mnt/c/Users/HAng3/Documents/wafer-defect-library/backend/venv/lib/python3.12/site-packages/gunicorn/app/wsgiapp.py", line 47, in load_wsgiapp
    return util.import_app(self.app_uri)
           ^^^^^^^^^^^^^^^^^^^^^^^^^^^^^
  File "/mnt/c/Users/HAng3/Documents/wafer-defect-library/backend/venv/lib/python3.12/site-packages/gunicorn/util.py", line 370, in import_app
    mod = importlib.import_module(module)
          ^^^^^^^^^^^^^^^^^^^^^^^^^^^^^^^
  File "/usr/lib/python3.12/importlib/__init__.py", line 90, in import_module
    return _bootstrap._gcd_import(name[level:], package, level)
           ^^^^^^^^^^^^^^^^^^^^^^^^^^^^^^^^^^^^^^^^^^^^^^^^^^^^
  File "<frozen importlib._bootstrap>", line 1387, in _gcd_import
  File "<frozen importlib._bootstrap>", line 1360, in _find_and_load
  File "<frozen importlib._bootstrap>", line 1331, in _find_and_load_unlocked
  File "<frozen importlib._bootstrap>", line 935, in _load_unlocked
  File "<frozen importlib._bootstrap_external>", line 995, in exec_module
  File "<frozen importlib._bootstrap>", line 488, in _call_with_frames_removed
  File "/mnt/c/Users/HAng3/Documents/wafer-defect-library/backend/app.py", line 5, in <module>
    from flask_cors import CORS
ModuleNotFoundError: No module named 'flask_cors'
[2025-04-09 08:43:21 +0800] [1614] [ERROR] Exception in worker process
Traceback (most recent call last):
  File "/mnt/c/Users/HAng3/Documents/wafer-defect-library/backend/venv/lib/python3.12/site-packages/gunicorn/arbiter.py", line 608, in spawn_worker
    worker.init_process()
  File "/mnt/c/Users/HAng3/Documents/wafer-defect-library/backend/venv/lib/python3.12/site-packages/gunicorn/workers/base.py", line 135, in init_process
    self.load_wsgi()
  File "/mnt/c/Users/HAng3/Documents/wafer-defect-library/backend/venv/lib/python3.12/site-packages/gunicorn/workers/base.py", line 147, in load_wsgi
    self.wsgi = self.app.wsgi()
                ^^^^^^^^^^^^^^^
  File "/mnt/c/Users/HAng3/Documents/wafer-defect-library/backend/venv/lib/python3.12/site-packages/gunicorn/app/base.py", line 66, in wsgi
    self.callable = self.load()
                    ^^^^^^^^^^^
  File "/mnt/c/Users/HAng3/Documents/wafer-defect-library/backend/venv/lib/python3.12/site-packages/gunicorn/app/wsgiapp.py", line 57, in load
    return self.load_wsgiapp()
           ^^^^^^^^^^^^^^^^^^^
  File "/mnt/c/Users/HAng3/Documents/wafer-defect-library/backend/venv/lib/python3.12/site-packages/gunicorn/app/wsgiapp.py", line 47, in load_wsgiapp
    return util.import_app(self.app_uri)
           ^^^^^^^^^^^^^^^^^^^^^^^^^^^^^
  File "/mnt/c/Users/HAng3/Documents/wafer-defect-library/backend/venv/lib/python3.12/site-packages/gunicorn/util.py", line 370, in import_app
    mod = importlib.import_module(module)
          ^^^^^^^^^^^^^^^^^^^^^^^^^^^^^^^
  File "/usr/lib/python3.12/importlib/__init__.py", line 90, in import_module
    return _bootstrap._gcd_import(name[level:], package, level)
           ^^^^^^^^^^^^^^^^^^^^^^^^^^^^^^^^^^^^^^^^^^^^^^^^^^^^
  File "<frozen importlib._bootstrap>", line 1387, in _gcd_import
  File "<frozen importlib._bootstrap>", line 1360, in _find_and_load
  File "<frozen importlib._bootstrap>", line 1331, in _find_and_load_unlocked
  File "<frozen importlib._bootstrap>", line 935, in _load_unlocked
  File "<frozen importlib._bootstrap_external>", line 995, in exec_module
  File "<frozen importlib._bootstrap>", line 488, in _call_with_frames_removed
  File "/mnt/c/Users/HAng3/Documents/wafer-defect-library/backend/app.py", line 5, in <module>
    from flask_cors import CORS
ModuleNotFoundError: No module named 'flask_cors'
[2025-04-09 08:43:22 +0800] [1613] [INFO] Worker exiting (pid: 1613)
[2025-04-09 08:43:21 +0800] [1608] [ERROR] Exception in worker process
Traceback (most recent call last):
  File "/mnt/c/Users/HAng3/Documents/wafer-defect-library/backend/venv/lib/python3.12/site-packages/gunicorn/arbiter.py", line 608, in spawn_worker
    worker.init_process()
  File "/mnt/c/Users/HAng3/Documents/wafer-defect-library/backend/venv/lib/python3.12/site-packages/gunicorn/workers/base.py", line 135, in init_process
    self.load_wsgi()
  File "/mnt/c/Users/HAng3/Documents/wafer-defect-library/backend/venv/lib/python3.12/site-packages/gunicorn/workers/base.py", line 147, in load_wsgi
    self.wsgi = self.app.wsgi()
                ^^^^^^^^^^^^^^^
  File "/mnt/c/Users/HAng3/Documents/wafer-defect-library/backend/venv/lib/python3.12/site-packages/gunicorn/app/base.py", line 66, in wsgi
    self.callable = self.load()
                    ^^^^^^^^^^^
  File "/mnt/c/Users/HAng3/Documents/wafer-defect-library/backend/venv/lib/python3.12/site-packages/gunicorn/app/wsgiapp.py", line 57, in load
    return self.load_wsgiapp()
           ^^^^^^^^^^^^^^^^^^^
  File "/mnt/c/Users/HAng3/Documents/wafer-defect-library/backend/venv/lib/python3.12/site-packages/gunicorn/app/wsgiapp.py", line 47, in load_wsgiapp
    return util.import_app(self.app_uri)
           ^^^^^^^^^^^^^^^^^^^^^^^^^^^^^
  File "/mnt/c/Users/HAng3/Documents/wafer-defect-library/backend/venv/lib/python3.12/site-packages/gunicorn/util.py", line 370, in import_app
    mod = importlib.import_module(module)
          ^^^^^^^^^^^^^^^^^^^^^^^^^^^^^^^
  File "/usr/lib/python3.12/importlib/__init__.py", line 90, in import_module
    return _bootstrap._gcd_import(name[level:], package, level)
           ^^^^^^^^^^^^^^^^^^^^^^^^^^^^^^^^^^^^^^^^^^^^^^^^^^^^
  File "<frozen importlib._bootstrap>", line 1387, in _gcd_import
  File "<frozen importlib._bootstrap>", line 1360, in _find_and_load
  File "<frozen importlib._bootstrap>", line 1331, in _find_and_load_unlocked
  File "<frozen importlib._bootstrap>", line 935, in _load_unlocked
  File "<frozen importlib._bootstrap_external>", line 995, in exec_module
  File "<frozen importlib._bootstrap>", line 488, in _call_with_frames_removed
  File "/mnt/c/Users/HAng3/Documents/wafer-defect-library/backend/app.py", line 5, in <module>
    from flask_cors import CORS
ModuleNotFoundError: No module named 'flask_cors'
[2025-04-09 08:43:22 +0800] [1614] [INFO] Worker exiting (pid: 1614)
[2025-04-09 08:43:22 +0800] [1608] [INFO] Worker exiting (pid: 1608)
[2025-04-09 08:43:22 +0800] [1601] [ERROR] Worker (pid:1604) exited with code 3
[2025-04-09 08:43:22 +0800] [1601] [ERROR] Worker (pid:1607) exited with code 3
[2025-04-09 08:43:22 +0800] [1601] [ERROR] Worker (pid:1608) exited with code 3
[2025-04-09 08:43:22 +0800] [1606] [ERROR] Exception in worker process
Traceback (most recent call last):
  File "/mnt/c/Users/HAng3/Documents/wafer-defect-library/backend/venv/lib/python3.12/site-packages/gunicorn/arbiter.py", line 608, in spawn_worker
    worker.init_process()
  File "/mnt/c/Users/HAng3/Documents/wafer-defect-library/backend/venv/lib/python3.12/site-packages/gunicorn/workers/base.py", line 135, in init_process
    self.load_wsgi()
  File "/mnt/c/Users/HAng3/Documents/wafer-defect-library/backend/venv/lib/python3.12/site-packages/gunicorn/workers/base.py", line 147, in load_wsgi
    self.wsgi = self.app.wsgi()
                ^^^^^^^^^^^^^^^
  File "/mnt/c/Users/HAng3/Documents/wafer-defect-library/backend/venv/lib/python3.12/site-packages/gunicorn/app/base.py", line 66, in wsgi
    self.callable = self.load()
                    ^^^^^^^^^^^
  File "/mnt/c/Users/HAng3/Documents/wafer-defect-library/backend/venv/lib/python3.12/site-packages/gunicorn/app/wsgiapp.py", line 57, in load
    return self.load_wsgiapp()
           ^^^^^^^^^^^^^^^^^^^
  File "/mnt/c/Users/HAng3/Documents/wafer-defect-library/backend/venv/lib/python3.12/site-packages/gunicorn/app/wsgiapp.py", line 47, in load_wsgiapp
    return util.import_app(self.app_uri)
           ^^^^^^^^^^^^^^^^^^^^^^^^^^^^^
  File "/mnt/c/Users/HAng3/Documents/wafer-defect-library/backend/venv/lib/python3.12/site-packages/gunicorn/util.py", line 370, in import_app
    mod = importlib.import_module(module)
          ^^^^^^^^^^^^^^^^^^^^^^^^^^^^^^^
  File "/usr/lib/python3.12/importlib/__init__.py", line 90, in import_module
    return _bootstrap._gcd_import(name[level:], package, level)
           ^^^^^^^^^^^^^^^^^^^^^^^^^^^^^^^^^^^^^^^^^^^^^^^^^^^^
  File "<frozen importlib._bootstrap>", line 1387, in _gcd_import
  File "<frozen importlib._bootstrap>", line 1360, in _find_and_load
  File "<frozen importlib._bootstrap>", line 1331, in _find_and_load_unlocked
  File "<frozen importlib._bootstrap>", line 935, in _load_unlocked
  File "<frozen importlib._bootstrap_external>", line 995, in exec_module
  File "<frozen importlib._bootstrap>", line 488, in _call_with_frames_removed
  File "/mnt/c/Users/HAng3/Documents/wafer-defect-library/backend/app.py", line 5, in <module>
    from flask_cors import CORS
ModuleNotFoundError: No module named 'flask_cors'
[2025-04-09 08:43:23 +0800] [1606] [INFO] Worker exiting (pid: 1606)
[2025-04-09 08:43:23 +0800] [1611] [ERROR] Exception in worker process
Traceback (most recent call last):
  File "/mnt/c/Users/HAng3/Documents/wafer-defect-library/backend/venv/lib/python3.12/site-packages/gunicorn/arbiter.py", line 608, in spawn_worker
    worker.init_process()
  File "/mnt/c/Users/HAng3/Documents/wafer-defect-library/backend/venv/lib/python3.12/site-packages/gunicorn/workers/base.py", line 135, in init_process
    self.load_wsgi()
  File "/mnt/c/Users/HAng3/Documents/wafer-defect-library/backend/venv/lib/python3.12/site-packages/gunicorn/workers/base.py", line 147, in load_wsgi
    self.wsgi = self.app.wsgi()
                ^^^^^^^^^^^^^^^
  File "/mnt/c/Users/HAng3/Documents/wafer-defect-library/backend/venv/lib/python3.12/site-packages/gunicorn/app/base.py", line 66, in wsgi
    self.callable = self.load()
                    ^^^^^^^^^^^
  File "/mnt/c/Users/HAng3/Documents/wafer-defect-library/backend/venv/lib/python3.12/site-packages/gunicorn/app/wsgiapp.py", line 57, in load
    return self.load_wsgiapp()
           ^^^^^^^^^^^^^^^^^^^
  File "/mnt/c/Users/HAng3/Documents/wafer-defect-library/backend/venv/lib/python3.12/site-packages/gunicorn/app/wsgiapp.py", line 47, in load_wsgiapp
    return util.import_app(self.app_uri)
           ^^^^^^^^^^^^^^^^^^^^^^^^^^^^^
  File "/mnt/c/Users/HAng3/Documents/wafer-defect-library/backend/venv/lib/python3.12/site-packages/gunicorn/util.py", line 370, in import_app
    mod = importlib.import_module(module)
          ^^^^^^^^^^^^^^^^^^^^^^^^^^^^^^^
  File "/usr/lib/python3.12/importlib/__init__.py", line 90, in import_module
    return _bootstrap._gcd_import(name[level:], package, level)
           ^^^^^^^^^^^^^^^^^^^^^^^^^^^^^^^^^^^^^^^^^^^^^^^^^^^^
  File "<frozen importlib._bootstrap>", line 1387, in _gcd_import
  File "<frozen importlib._bootstrap>", line 1360, in _find_and_load
  File "<frozen importlib._bootstrap>", line 1331, in _find_and_load_unlocked
  File "<frozen importlib._bootstrap>", line 935, in _load_unlocked
  File "<frozen importlib._bootstrap_external>", line 995, in exec_module
  File "<frozen importlib._bootstrap>", line 488, in _call_with_frames_removed
  File "/mnt/c/Users/HAng3/Documents/wafer-defect-library/backend/app.py", line 5, in <module>
    from flask_cors import CORS
ModuleNotFoundError: No module named 'flask_cors'
[2025-04-09 08:43:23 +0800] [1611] [INFO] Worker exiting (pid: 1611)
[2025-04-09 08:43:23 +0800] [1610] [ERROR] Exception in worker process
Traceback (most recent call last):
  File "/mnt/c/Users/HAng3/Documents/wafer-defect-library/backend/venv/lib/python3.12/site-packages/gunicorn/arbiter.py", line 608, in spawn_worker
    worker.init_process()
  File "/mnt/c/Users/HAng3/Documents/wafer-defect-library/backend/venv/lib/python3.12/site-packages/gunicorn/workers/base.py", line 135, in init_process
    self.load_wsgi()
  File "/mnt/c/Users/HAng3/Documents/wafer-defect-library/backend/venv/lib/python3.12/site-packages/gunicorn/workers/base.py", line 147, in load_wsgi
    self.wsgi = self.app.wsgi()
                ^^^^^^^^^^^^^^^
  File "/mnt/c/Users/HAng3/Documents/wafer-defect-library/backend/venv/lib/python3.12/site-packages/gunicorn/app/base.py", line 66, in wsgi
    self.callable = self.load()
                    ^^^^^^^^^^^
  File "/mnt/c/Users/HAng3/Documents/wafer-defect-library/backend/venv/lib/python3.12/site-packages/gunicorn/app/wsgiapp.py", line 57, in load
    return self.load_wsgiapp()
           ^^^^^^^^^^^^^^^^^^^
  File "/mnt/c/Users/HAng3/Documents/wafer-defect-library/backend/venv/lib/python3.12/site-packages/gunicorn/app/wsgiapp.py", line 47, in load_wsgiapp
    return util.import_app(self.app_uri)
           ^^^^^^^^^^^^^^^^^^^^^^^^^^^^^
  File "/mnt/c/Users/HAng3/Documents/wafer-defect-library/backend/venv/lib/python3.12/site-packages/gunicorn/util.py", line 370, in import_app
    mod = importlib.import_module(module)
          ^^^^^^^^^^^^^^^^^^^^^^^^^^^^^^^
  File "/usr/lib/python3.12/importlib/__init__.py", line 90, in import_module
    return _bootstrap._gcd_import(name[level:], package, level)
           ^^^^^^^^^^^^^^^^^^^^^^^^^^^^^^^^^^^^^^^^^^^^^^^^^^^^
  File "<frozen importlib._bootstrap>", line 1387, in _gcd_import
  File "<frozen importlib._bootstrap>", line 1360, in _find_and_load
  File "<frozen importlib._bootstrap>", line 1331, in _find_and_load_unlocked
  File "<frozen importlib._bootstrap>", line 935, in _load_unlocked
  File "<frozen importlib._bootstrap_external>", line 995, in exec_module
  File "<frozen importlib._bootstrap>", line 488, in _call_with_frames_removed
  File "/mnt/c/Users/HAng3/Documents/wafer-defect-library/backend/app.py", line 5, in <module>
    from flask_cors import CORS
ModuleNotFoundError: No module named 'flask_cors'
[2025-04-09 08:43:23 +0800] [1610] [INFO] Worker exiting (pid: 1610)
[2025-04-09 08:43:23 +0800] [1616] [ERROR] Exception in worker process
Traceback (most recent call last):
  File "/mnt/c/Users/HAng3/Documents/wafer-defect-library/backend/venv/lib/python3.12/site-packages/gunicorn/arbiter.py", line 608, in spawn_worker
    worker.init_process()
  File "/mnt/c/Users/HAng3/Documents/wafer-defect-library/backend/venv/lib/python3.12/site-packages/gunicorn/workers/base.py", line 135, in init_process
    self.load_wsgi()
  File "/mnt/c/Users/HAng3/Documents/wafer-defect-library/backend/venv/lib/python3.12/site-packages/gunicorn/workers/base.py", line 147, in load_wsgi
    self.wsgi = self.app.wsgi()
                ^^^^^^^^^^^^^^^
  File "/mnt/c/Users/HAng3/Documents/wafer-defect-library/backend/venv/lib/python3.12/site-packages/gunicorn/app/base.py", line 66, in wsgi
    self.callable = self.load()
                    ^^^^^^^^^^^
  File "/mnt/c/Users/HAng3/Documents/wafer-defect-library/backend/venv/lib/python3.12/site-packages/gunicorn/app/wsgiapp.py", line 57, in load
    return self.load_wsgiapp()
           ^^^^^^^^^^^^^^^^^^^
  File "/mnt/c/Users/HAng3/Documents/wafer-defect-library/backend/venv/lib/python3.12/site-packages/gunicorn/app/wsgiapp.py", line 47, in load_wsgiapp
    return util.import_app(self.app_uri)
           ^^^^^^^^^^^^^^^^^^^^^^^^^^^^^
  File "/mnt/c/Users/HAng3/Documents/wafer-defect-library/backend/venv/lib/python3.12/site-packages/gunicorn/util.py", line 370, in import_app
    mod = importlib.import_module(module)
          ^^^^^^^^^^^^^^^^^^^^^^^^^^^^^^^
  File "/usr/lib/python3.12/importlib/__init__.py", line 90, in import_module
    return _bootstrap._gcd_import(name[level:], package, level)
           ^^^^^^^^^^^^^^^^^^^^^^^^^^^^^^^^^^^^^^^^^^^^^^^^^^^^
  File "<frozen importlib._bootstrap>", line 1387, in _gcd_import
  File "<frozen importlib._bootstrap>", line 1360, in _find_and_load
  File "<frozen importlib._bootstrap>", line 1331, in _find_and_load_unlocked
  File "<frozen importlib._bootstrap>", line 935, in _load_unlocked
  File "<frozen importlib._bootstrap_external>", line 995, in exec_module
  File "<frozen importlib._bootstrap>", line 488, in _call_with_frames_removed
  File "/mnt/c/Users/HAng3/Documents/wafer-defect-library/backend/app.py", line 5, in <module>
    from flask_cors import CORS
ModuleNotFoundError: No module named 'flask_cors'
[2025-04-09 08:43:23 +0800] [1617] [ERROR] Exception in worker process
Traceback (most recent call last):
  File "/mnt/c/Users/HAng3/Documents/wafer-defect-library/backend/venv/lib/python3.12/site-packages/gunicorn/arbiter.py", line 608, in spawn_worker
    worker.init_process()
  File "/mnt/c/Users/HAng3/Documents/wafer-defect-library/backend/venv/lib/python3.12/site-packages/gunicorn/workers/base.py", line 135, in init_process
    self.load_wsgi()
  File "/mnt/c/Users/HAng3/Documents/wafer-defect-library/backend/venv/lib/python3.12/site-packages/gunicorn/workers/base.py", line 147, in load_wsgi
    self.wsgi = self.app.wsgi()
                ^^^^^^^^^^^^^^^
  File "/mnt/c/Users/HAng3/Documents/wafer-defect-library/backend/venv/lib/python3.12/site-packages/gunicorn/app/base.py", line 66, in wsgi
    self.callable = self.load()
                    ^^^^^^^^^^^
  File "/mnt/c/Users/HAng3/Documents/wafer-defect-library/backend/venv/lib/python3.12/site-packages/gunicorn/app/wsgiapp.py", line 57, in load
    return self.load_wsgiapp()
           ^^^^^^^^^^^^^^^^^^^
  File "/mnt/c/Users/HAng3/Documents/wafer-defect-library/backend/venv/lib/python3.12/site-packages/gunicorn/app/wsgiapp.py", line 47, in load_wsgiapp
    return util.import_app(self.app_uri)
           ^^^^^^^^^^^^^^^^^^^^^^^^^^^^^
  File "/mnt/c/Users/HAng3/Documents/wafer-defect-library/backend/venv/lib/python3.12/site-packages/gunicorn/util.py", line 370, in import_app
    mod = importlib.import_module(module)
          ^^^^^^^^^^^^^^^^^^^^^^^^^^^^^^^
  File "/usr/lib/python3.12/importlib/__init__.py", line 90, in import_module
    return _bootstrap._gcd_import(name[level:], package, level)
           ^^^^^^^^^^^^^^^^^^^^^^^^^^^^^^^^^^^^^^^^^^^^^^^^^^^^
  File "<frozen importlib._bootstrap>", line 1387, in _gcd_import
  File "<frozen importlib._bootstrap>", line 1360, in _find_and_load
  File "<frozen importlib._bootstrap>", line 1331, in _find_and_load_unlocked
  File "<frozen importlib._bootstrap>", line 935, in _load_unlocked
  File "<frozen importlib._bootstrap_external>", line 995, in exec_module
  File "<frozen importlib._bootstrap>", line 488, in _call_with_frames_removed
  File "/mnt/c/Users/HAng3/Documents/wafer-defect-library/backend/app.py", line 5, in <module>
    from flask_cors import CORS
ModuleNotFoundError: No module named 'flask_cors'
[2025-04-09 08:43:23 +0800] [1616] [INFO] Worker exiting (pid: 1616)
[2025-04-09 08:43:23 +0800] [1617] [INFO] Worker exiting (pid: 1617)
[2025-04-09 08:43:24 +0800] [1618] [ERROR] Exception in worker process
Traceback (most recent call last):
  File "/mnt/c/Users/HAng3/Documents/wafer-defect-library/backend/venv/lib/python3.12/site-packages/gunicorn/arbiter.py", line 608, in spawn_worker
    worker.init_process()
  File "/mnt/c/Users/HAng3/Documents/wafer-defect-library/backend/venv/lib/python3.12/site-packages/gunicorn/workers/base.py", line 135, in init_process
    self.load_wsgi()
  File "/mnt/c/Users/HAng3/Documents/wafer-defect-library/backend/venv/lib/python3.12/site-packages/gunicorn/workers/base.py", line 147, in load_wsgi
    self.wsgi = self.app.wsgi()
                ^^^^^^^^^^^^^^^
  File "/mnt/c/Users/HAng3/Documents/wafer-defect-library/backend/venv/lib/python3.12/site-packages/gunicorn/app/base.py", line 66, in wsgi
    self.callable = self.load()
                    ^^^^^^^^^^^
  File "/mnt/c/Users/HAng3/Documents/wafer-defect-library/backend/venv/lib/python3.12/site-packages/gunicorn/app/wsgiapp.py", line 57, in load
    return self.load_wsgiapp()
           ^^^^^^^^^^^^^^^^^^^
  File "/mnt/c/Users/HAng3/Documents/wafer-defect-library/backend/venv/lib/python3.12/site-packages/gunicorn/app/wsgiapp.py", line 47, in load_wsgiapp
    return util.import_app(self.app_uri)
           ^^^^^^^^^^^^^^^^^^^^^^^^^^^^^
  File "/mnt/c/Users/HAng3/Documents/wafer-defect-library/backend/venv/lib/python3.12/site-packages/gunicorn/util.py", line 370, in import_app
    mod = importlib.import_module(module)
          ^^^^^^^^^^^^^^^^^^^^^^^^^^^^^^^
  File "/usr/lib/python3.12/importlib/__init__.py", line 90, in import_module
    return _bootstrap._gcd_import(name[level:], package, level)
           ^^^^^^^^^^^^^^^^^^^^^^^^^^^^^^^^^^^^^^^^^^^^^^^^^^^^
  File "<frozen importlib._bootstrap>", line 1387, in _gcd_import
  File "<frozen importlib._bootstrap>", line 1360, in _find_and_load
  File "<frozen importlib._bootstrap>", line 1331, in _find_and_load_unlocked
  File "<frozen importlib._bootstrap>", line 935, in _load_unlocked
  File "<frozen importlib._bootstrap_external>", line 995, in exec_module
  File "<frozen importlib._bootstrap>", line 488, in _call_with_frames_removed
  File "/mnt/c/Users/HAng3/Documents/wafer-defect-library/backend/app.py", line 5, in <module>
    from flask_cors import CORS
ModuleNotFoundError: No module named 'flask_cors'
[2025-04-09 08:43:24 +0800] [1618] [INFO] Worker exiting (pid: 1618)
[2025-04-09 09:40:52 +0800] [1672] [INFO] Starting gunicorn 23.0.0
[2025-04-09 09:40:52 +0800] [1672] [INFO] Listening at: http://127.0.0.1:8000 (1672)
[2025-04-09 09:40:52 +0800] [1672] [INFO] Using worker: sync
[2025-04-09 09:40:52 +0800] [1673] [INFO] Booting worker with pid: 1673
[2025-04-09 09:40:52 +0800] [1674] [INFO] Booting worker with pid: 1674
[2025-04-09 09:40:52 +0800] [1675] [INFO] Booting worker with pid: 1675
[2025-04-09 09:40:52 +0800] [1676] [INFO] Booting worker with pid: 1676
[2025-04-09 09:40:52 +0800] [1677] [INFO] Booting worker with pid: 1677
[2025-04-09 09:40:52 +0800] [1678] [INFO] Booting worker with pid: 1678
[2025-04-09 09:40:52 +0800] [1679] [INFO] Booting worker with pid: 1679
[2025-04-09 09:40:52 +0800] [1680] [INFO] Booting worker with pid: 1680
[2025-04-09 09:40:52 +0800] [1681] [INFO] Booting worker with pid: 1681
[2025-04-09 09:40:52 +0800] [1682] [INFO] Booting worker with pid: 1682
[2025-04-09 09:40:53 +0800] [1683] [INFO] Booting worker with pid: 1683
[2025-04-09 09:40:53 +0800] [1684] [INFO] Booting worker with pid: 1684
[2025-04-09 09:40:53 +0800] [1685] [INFO] Booting worker with pid: 1685
[2025-04-09 09:40:53 +0800] [1686] [INFO] Booting worker with pid: 1686
[2025-04-09 09:40:53 +0800] [1687] [INFO] Booting worker with pid: 1687
[2025-04-09 09:40:53 +0800] [1688] [INFO] Booting worker with pid: 1688
[2025-04-09 09:40:53 +0800] [1689] [INFO] Booting worker with pid: 1689
[2025-04-09 09:41:27 +0800] [1679] [ERROR] Exception in worker process
Traceback (most recent call last):
  File "/mnt/c/Users/HAng3/Documents/wafer-defect-library/backend/venv/lib/python3.12/site-packages/gunicorn/arbiter.py", line 608, in spawn_worker
    worker.init_process()
  File "/mnt/c/Users/HAng3/Documents/wafer-defect-library/backend/venv/lib/python3.12/site-packages/gunicorn/workers/base.py", line 135, in init_process
    self.load_wsgi()
  File "/mnt/c/Users/HAng3/Documents/wafer-defect-library/backend/venv/lib/python3.12/site-packages/gunicorn/workers/base.py", line 147, in load_wsgi
    self.wsgi = self.app.wsgi()
                ^^^^^^^^^^^^^^^
  File "/mnt/c/Users/HAng3/Documents/wafer-defect-library/backend/venv/lib/python3.12/site-packages/gunicorn/app/base.py", line 66, in wsgi
    self.callable = self.load()
                    ^^^^^^^^^^^
  File "/mnt/c/Users/HAng3/Documents/wafer-defect-library/backend/venv/lib/python3.12/site-packages/gunicorn/app/wsgiapp.py", line 57, in load
    return self.load_wsgiapp()
           ^^^^^^^^^^^^^^^^^^^
  File "/mnt/c/Users/HAng3/Documents/wafer-defect-library/backend/venv/lib/python3.12/site-packages/gunicorn/app/wsgiapp.py", line 47, in load_wsgiapp
    return util.import_app(self.app_uri)
           ^^^^^^^^^^^^^^^^^^^^^^^^^^^^^
  File "/mnt/c/Users/HAng3/Documents/wafer-defect-library/backend/venv/lib/python3.12/site-packages/gunicorn/util.py", line 370, in import_app
    mod = importlib.import_module(module)
          ^^^^^^^^^^^^^^^^^^^^^^^^^^^^^^^
  File "/usr/lib/python3.12/importlib/__init__.py", line 90, in import_module
    return _bootstrap._gcd_import(name[level:], package, level)
           ^^^^^^^^^^^^^^^^^^^^^^^^^^^^^^^^^^^^^^^^^^^^^^^^^^^^
  File "<frozen importlib._bootstrap>", line 1387, in _gcd_import
  File "<frozen importlib._bootstrap>", line 1360, in _find_and_load
  File "<frozen importlib._bootstrap>", line 1331, in _find_and_load_unlocked
  File "<frozen importlib._bootstrap>", line 935, in _load_unlocked
  File "<frozen importlib._bootstrap_external>", line 995, in exec_module
  File "<frozen importlib._bootstrap>", line 488, in _call_with_frames_removed
  File "/mnt/c/Users/HAng3/Documents/wafer-defect-library/backend/app.py", line 5, in <module>
    from flask_cors import CORS
ModuleNotFoundError: No module named 'flask_cors'
[2025-04-09 09:41:27 +0800] [1689] [ERROR] Exception in worker process
Traceback (most recent call last):
  File "/mnt/c/Users/HAng3/Documents/wafer-defect-library/backend/venv/lib/python3.12/site-packages/gunicorn/arbiter.py", line 608, in spawn_worker
    worker.init_process()
  File "/mnt/c/Users/HAng3/Documents/wafer-defect-library/backend/venv/lib/python3.12/site-packages/gunicorn/workers/base.py", line 135, in init_process
    self.load_wsgi()
  File "/mnt/c/Users/HAng3/Documents/wafer-defect-library/backend/venv/lib/python3.12/site-packages/gunicorn/workers/base.py", line 147, in load_wsgi
    self.wsgi = self.app.wsgi()
                ^^^^^^^^^^^^^^^
  File "/mnt/c/Users/HAng3/Documents/wafer-defect-library/backend/venv/lib/python3.12/site-packages/gunicorn/app/base.py", line 66, in wsgi
    self.callable = self.load()
                    ^^^^^^^^^^^
  File "/mnt/c/Users/HAng3/Documents/wafer-defect-library/backend/venv/lib/python3.12/site-packages/gunicorn/app/wsgiapp.py", line 57, in load
    return self.load_wsgiapp()
           ^^^^^^^^^^^^^^^^^^^
  File "/mnt/c/Users/HAng3/Documents/wafer-defect-library/backend/venv/lib/python3.12/site-packages/gunicorn/app/wsgiapp.py", line 47, in load_wsgiapp
    return util.import_app(self.app_uri)
           ^^^^^^^^^^^^^^^^^^^^^^^^^^^^^
  File "/mnt/c/Users/HAng3/Documents/wafer-defect-library/backend/venv/lib/python3.12/site-packages/gunicorn/util.py", line 370, in import_app
    mod = importlib.import_module(module)
          ^^^^^^^^^^^^^^^^^^^^^^^^^^^^^^^
  File "/usr/lib/python3.12/importlib/__init__.py", line 90, in import_module
    return _bootstrap._gcd_import(name[level:], package, level)
           ^^^^^^^^^^^^^^^^^^^^^^^^^^^^^^^^^^^^^^^^^^^^^^^^^^^^
  File "<frozen importlib._bootstrap>", line 1387, in _gcd_import
  File "<frozen importlib._bootstrap>", line 1360, in _find_and_load
  File "<frozen importlib._bootstrap>", line 1331, in _find_and_load_unlocked
  File "<frozen importlib._bootstrap>", line 935, in _load_unlocked
  File "<frozen importlib._bootstrap_external>", line 995, in exec_module
  File "<frozen importlib._bootstrap>", line 488, in _call_with_frames_removed
  File "/mnt/c/Users/HAng3/Documents/wafer-defect-library/backend/app.py", line 5, in <module>
    from flask_cors import CORS
ModuleNotFoundError: No module named 'flask_cors'
[2025-04-09 09:41:27 +0800] [1685] [ERROR] Exception in worker process
Traceback (most recent call last):
  File "/mnt/c/Users/HAng3/Documents/wafer-defect-library/backend/venv/lib/python3.12/site-packages/gunicorn/arbiter.py", line 608, in spawn_worker
    worker.init_process()
  File "/mnt/c/Users/HAng3/Documents/wafer-defect-library/backend/venv/lib/python3.12/site-packages/gunicorn/workers/base.py", line 135, in init_process
    self.load_wsgi()
  File "/mnt/c/Users/HAng3/Documents/wafer-defect-library/backend/venv/lib/python3.12/site-packages/gunicorn/workers/base.py", line 147, in load_wsgi
    self.wsgi = self.app.wsgi()
                ^^^^^^^^^^^^^^^
  File "/mnt/c/Users/HAng3/Documents/wafer-defect-library/backend/venv/lib/python3.12/site-packages/gunicorn/app/base.py", line 66, in wsgi
    self.callable = self.load()
                    ^^^^^^^^^^^
  File "/mnt/c/Users/HAng3/Documents/wafer-defect-library/backend/venv/lib/python3.12/site-packages/gunicorn/app/wsgiapp.py", line 57, in load
    return self.load_wsgiapp()
           ^^^^^^^^^^^^^^^^^^^
  File "/mnt/c/Users/HAng3/Documents/wafer-defect-library/backend/venv/lib/python3.12/site-packages/gunicorn/app/wsgiapp.py", line 47, in load_wsgiapp
    return util.import_app(self.app_uri)
           ^^^^^^^^^^^^^^^^^^^^^^^^^^^^^
  File "/mnt/c/Users/HAng3/Documents/wafer-defect-library/backend/venv/lib/python3.12/site-packages/gunicorn/util.py", line 370, in import_app
    mod = importlib.import_module(module)
          ^^^^^^^^^^^^^^^^^^^^^^^^^^^^^^^
  File "/usr/lib/python3.12/importlib/__init__.py", line 90, in import_module
    return _bootstrap._gcd_import(name[level:], package, level)
           ^^^^^^^^^^^^^^^^^^^^^^^^^^^^^^^^^^^^^^^^^^^^^^^^^^^^
  File "<frozen importlib._bootstrap>", line 1387, in _gcd_import
  File "<frozen importlib._bootstrap>", line 1360, in _find_and_load
  File "<frozen importlib._bootstrap>", line 1331, in _find_and_load_unlocked
  File "<frozen importlib._bootstrap>", line 935, in _load_unlocked
  File "<frozen importlib._bootstrap_external>", line 995, in exec_module
  File "<frozen importlib._bootstrap>", line 488, in _call_with_frames_removed
  File "/mnt/c/Users/HAng3/Documents/wafer-defect-library/backend/app.py", line 5, in <module>
    from flask_cors import CORS
ModuleNotFoundError: No module named 'flask_cors'
[2025-04-09 09:41:27 +0800] [1683] [ERROR] Exception in worker process
Traceback (most recent call last):
  File "/mnt/c/Users/HAng3/Documents/wafer-defect-library/backend/venv/lib/python3.12/site-packages/gunicorn/arbiter.py", line 608, in spawn_worker
    worker.init_process()
  File "/mnt/c/Users/HAng3/Documents/wafer-defect-library/backend/venv/lib/python3.12/site-packages/gunicorn/workers/base.py", line 135, in init_process
    self.load_wsgi()
  File "/mnt/c/Users/HAng3/Documents/wafer-defect-library/backend/venv/lib/python3.12/site-packages/gunicorn/workers/base.py", line 147, in load_wsgi
    self.wsgi = self.app.wsgi()
                ^^^^^^^^^^^^^^^
  File "/mnt/c/Users/HAng3/Documents/wafer-defect-library/backend/venv/lib/python3.12/site-packages/gunicorn/app/base.py", line 66, in wsgi
    self.callable = self.load()
                    ^^^^^^^^^^^
  File "/mnt/c/Users/HAng3/Documents/wafer-defect-library/backend/venv/lib/python3.12/site-packages/gunicorn/app/wsgiapp.py", line 57, in load
    return self.load_wsgiapp()
           ^^^^^^^^^^^^^^^^^^^
  File "/mnt/c/Users/HAng3/Documents/wafer-defect-library/backend/venv/lib/python3.12/site-packages/gunicorn/app/wsgiapp.py", line 47, in load_wsgiapp
    return util.import_app(self.app_uri)
           ^^^^^^^^^^^^^^^^^^^^^^^^^^^^^
  File "/mnt/c/Users/HAng3/Documents/wafer-defect-library/backend/venv/lib/python3.12/site-packages/gunicorn/util.py", line 370, in import_app
    mod = importlib.import_module(module)
          ^^^^^^^^^^^^^^^^^^^^^^^^^^^^^^^
  File "/usr/lib/python3.12/importlib/__init__.py", line 90, in import_module
    return _bootstrap._gcd_import(name[level:], package, level)
           ^^^^^^^^^^^^^^^^^^^^^^^^^^^^^^^^^^^^^^^^^^^^^^^^^^^^
  File "<frozen importlib._bootstrap>", line 1387, in _gcd_import
  File "<frozen importlib._bootstrap>", line 1360, in _find_and_load
  File "<frozen importlib._bootstrap>", line 1331, in _find_and_load_unlocked
  File "<frozen importlib._bootstrap>", line 935, in _load_unlocked
  File "<frozen importlib._bootstrap_external>", line 995, in exec_module
  File "<frozen importlib._bootstrap>", line 488, in _call_with_frames_removed
  File "/mnt/c/Users/HAng3/Documents/wafer-defect-library/backend/app.py", line 5, in <module>
    from flask_cors import CORS
ModuleNotFoundError: No module named 'flask_cors'
[2025-04-09 09:41:27 +0800] [1681] [ERROR] Exception in worker process
Traceback (most recent call last):
  File "/mnt/c/Users/HAng3/Documents/wafer-defect-library/backend/venv/lib/python3.12/site-packages/gunicorn/arbiter.py", line 608, in spawn_worker
    worker.init_process()
  File "/mnt/c/Users/HAng3/Documents/wafer-defect-library/backend/venv/lib/python3.12/site-packages/gunicorn/workers/base.py", line 135, in init_process
    self.load_wsgi()
  File "/mnt/c/Users/HAng3/Documents/wafer-defect-library/backend/venv/lib/python3.12/site-packages/gunicorn/workers/base.py", line 147, in load_wsgi
    self.wsgi = self.app.wsgi()
                ^^^^^^^^^^^^^^^
  File "/mnt/c/Users/HAng3/Documents/wafer-defect-library/backend/venv/lib/python3.12/site-packages/gunicorn/app/base.py", line 66, in wsgi
    self.callable = self.load()
                    ^^^^^^^^^^^
  File "/mnt/c/Users/HAng3/Documents/wafer-defect-library/backend/venv/lib/python3.12/site-packages/gunicorn/app/wsgiapp.py", line 57, in load
    return self.load_wsgiapp()
           ^^^^^^^^^^^^^^^^^^^
  File "/mnt/c/Users/HAng3/Documents/wafer-defect-library/backend/venv/lib/python3.12/site-packages/gunicorn/app/wsgiapp.py", line 47, in load_wsgiapp
    return util.import_app(self.app_uri)
           ^^^^^^^^^^^^^^^^^^^^^^^^^^^^^
  File "/mnt/c/Users/HAng3/Documents/wafer-defect-library/backend/venv/lib/python3.12/site-packages/gunicorn/util.py", line 370, in import_app
    mod = importlib.import_module(module)
          ^^^^^^^^^^^^^^^^^^^^^^^^^^^^^^^
  File "/usr/lib/python3.12/importlib/__init__.py", line 90, in import_module
    return _bootstrap._gcd_import(name[level:], package, level)
           ^^^^^^^^^^^^^^^^^^^^^^^^^^^^^^^^^^^^^^^^^^^^^^^^^^^^
  File "<frozen importlib._bootstrap>", line 1387, in _gcd_import
  File "<frozen importlib._bootstrap>", line 1360, in _find_and_load
  File "<frozen importlib._bootstrap>", line 1331, in _find_and_load_unlocked
  File "<frozen importlib._bootstrap>", line 935, in _load_unlocked
  File "<frozen importlib._bootstrap_external>", line 995, in exec_module
  File "<frozen importlib._bootstrap>", line 488, in _call_with_frames_removed
  File "/mnt/c/Users/HAng3/Documents/wafer-defect-library/backend/app.py", line 5, in <module>
    from flask_cors import CORS
ModuleNotFoundError: No module named 'flask_cors'
[2025-04-09 09:41:28 +0800] [1679] [INFO] Worker exiting (pid: 1679)
[2025-04-09 09:41:27 +0800] [1680] [ERROR] Exception in worker process
Traceback (most recent call last):
  File "/mnt/c/Users/HAng3/Documents/wafer-defect-library/backend/venv/lib/python3.12/site-packages/gunicorn/arbiter.py", line 608, in spawn_worker
    worker.init_process()
  File "/mnt/c/Users/HAng3/Documents/wafer-defect-library/backend/venv/lib/python3.12/site-packages/gunicorn/workers/base.py", line 135, in init_process
    self.load_wsgi()
  File "/mnt/c/Users/HAng3/Documents/wafer-defect-library/backend/venv/lib/python3.12/site-packages/gunicorn/workers/base.py", line 147, in load_wsgi
    self.wsgi = self.app.wsgi()
                ^^^^^^^^^^^^^^^
  File "/mnt/c/Users/HAng3/Documents/wafer-defect-library/backend/venv/lib/python3.12/site-packages/gunicorn/app/base.py", line 66, in wsgi
    self.callable = self.load()
                    ^^^^^^^^^^^
  File "/mnt/c/Users/HAng3/Documents/wafer-defect-library/backend/venv/lib/python3.12/site-packages/gunicorn/app/wsgiapp.py", line 57, in load
    return self.load_wsgiapp()
           ^^^^^^^^^^^^^^^^^^^
  File "/mnt/c/Users/HAng3/Documents/wafer-defect-library/backend/venv/lib/python3.12/site-packages/gunicorn/app/wsgiapp.py", line 47, in load_wsgiapp
    return util.import_app(self.app_uri)
           ^^^^^^^^^^^^^^^^^^^^^^^^^^^^^
  File "/mnt/c/Users/HAng3/Documents/wafer-defect-library/backend/venv/lib/python3.12/site-packages/gunicorn/util.py", line 370, in import_app
    mod = importlib.import_module(module)
          ^^^^^^^^^^^^^^^^^^^^^^^^^^^^^^^
  File "/usr/lib/python3.12/importlib/__init__.py", line 90, in import_module
    return _bootstrap._gcd_import(name[level:], package, level)
           ^^^^^^^^^^^^^^^^^^^^^^^^^^^^^^^^^^^^^^^^^^^^^^^^^^^^
  File "<frozen importlib._bootstrap>", line 1387, in _gcd_import
  File "<frozen importlib._bootstrap>", line 1360, in _find_and_load
  File "<frozen importlib._bootstrap>", line 1331, in _find_and_load_unlocked
  File "<frozen importlib._bootstrap>", line 935, in _load_unlocked
  File "<frozen importlib._bootstrap_external>", line 995, in exec_module
  File "<frozen importlib._bootstrap>", line 488, in _call_with_frames_removed
  File "/mnt/c/Users/HAng3/Documents/wafer-defect-library/backend/app.py", line 5, in <module>
    from flask_cors import CORS
ModuleNotFoundError: No module named 'flask_cors'
[2025-04-09 09:41:27 +0800] [1686] [ERROR] Exception in worker process
Traceback (most recent call last):
  File "/mnt/c/Users/HAng3/Documents/wafer-defect-library/backend/venv/lib/python3.12/site-packages/gunicorn/arbiter.py", line 608, in spawn_worker
    worker.init_process()
  File "/mnt/c/Users/HAng3/Documents/wafer-defect-library/backend/venv/lib/python3.12/site-packages/gunicorn/workers/base.py", line 135, in init_process
    self.load_wsgi()
  File "/mnt/c/Users/HAng3/Documents/wafer-defect-library/backend/venv/lib/python3.12/site-packages/gunicorn/workers/base.py", line 147, in load_wsgi
    self.wsgi = self.app.wsgi()
                ^^^^^^^^^^^^^^^
  File "/mnt/c/Users/HAng3/Documents/wafer-defect-library/backend/venv/lib/python3.12/site-packages/gunicorn/app/base.py", line 66, in wsgi
    self.callable = self.load()
                    ^^^^^^^^^^^
  File "/mnt/c/Users/HAng3/Documents/wafer-defect-library/backend/venv/lib/python3.12/site-packages/gunicorn/app/wsgiapp.py", line 57, in load
    return self.load_wsgiapp()
           ^^^^^^^^^^^^^^^^^^^
  File "/mnt/c/Users/HAng3/Documents/wafer-defect-library/backend/venv/lib/python3.12/site-packages/gunicorn/app/wsgiapp.py", line 47, in load_wsgiapp
    return util.import_app(self.app_uri)
           ^^^^^^^^^^^^^^^^^^^^^^^^^^^^^
  File "/mnt/c/Users/HAng3/Documents/wafer-defect-library/backend/venv/lib/python3.12/site-packages/gunicorn/util.py", line 370, in import_app
    mod = importlib.import_module(module)
          ^^^^^^^^^^^^^^^^^^^^^^^^^^^^^^^
  File "/usr/lib/python3.12/importlib/__init__.py", line 90, in import_module
    return _bootstrap._gcd_import(name[level:], package, level)
           ^^^^^^^^^^^^^^^^^^^^^^^^^^^^^^^^^^^^^^^^^^^^^^^^^^^^
  File "<frozen importlib._bootstrap>", line 1387, in _gcd_import
  File "<frozen importlib._bootstrap>", line 1360, in _find_and_load
  File "<frozen importlib._bootstrap>", line 1331, in _find_and_load_unlocked
  File "<frozen importlib._bootstrap>", line 935, in _load_unlocked
  File "<frozen importlib._bootstrap_external>", line 995, in exec_module
  File "<frozen importlib._bootstrap>", line 488, in _call_with_frames_removed
  File "/mnt/c/Users/HAng3/Documents/wafer-defect-library/backend/app.py", line 5, in <module>
    from flask_cors import CORS
ModuleNotFoundError: No module named 'flask_cors'
[2025-04-09 09:41:27 +0800] [1678] [ERROR] Exception in worker process
Traceback (most recent call last):
  File "/mnt/c/Users/HAng3/Documents/wafer-defect-library/backend/venv/lib/python3.12/site-packages/gunicorn/arbiter.py", line 608, in spawn_worker
    worker.init_process()
  File "/mnt/c/Users/HAng3/Documents/wafer-defect-library/backend/venv/lib/python3.12/site-packages/gunicorn/workers/base.py", line 135, in init_process
    self.load_wsgi()
  File "/mnt/c/Users/HAng3/Documents/wafer-defect-library/backend/venv/lib/python3.12/site-packages/gunicorn/workers/base.py", line 147, in load_wsgi
    self.wsgi = self.app.wsgi()
                ^^^^^^^^^^^^^^^
  File "/mnt/c/Users/HAng3/Documents/wafer-defect-library/backend/venv/lib/python3.12/site-packages/gunicorn/app/base.py", line 66, in wsgi
    self.callable = self.load()
                    ^^^^^^^^^^^
  File "/mnt/c/Users/HAng3/Documents/wafer-defect-library/backend/venv/lib/python3.12/site-packages/gunicorn/app/wsgiapp.py", line 57, in load
    return self.load_wsgiapp()
           ^^^^^^^^^^^^^^^^^^^
  File "/mnt/c/Users/HAng3/Documents/wafer-defect-library/backend/venv/lib/python3.12/site-packages/gunicorn/app/wsgiapp.py", line 47, in load_wsgiapp
    return util.import_app(self.app_uri)
           ^^^^^^^^^^^^^^^^^^^^^^^^^^^^^
  File "/mnt/c/Users/HAng3/Documents/wafer-defect-library/backend/venv/lib/python3.12/site-packages/gunicorn/util.py", line 370, in import_app
    mod = importlib.import_module(module)
          ^^^^^^^^^^^^^^^^^^^^^^^^^^^^^^^
  File "/usr/lib/python3.12/importlib/__init__.py", line 90, in import_module
    return _bootstrap._gcd_import(name[level:], package, level)
           ^^^^^^^^^^^^^^^^^^^^^^^^^^^^^^^^^^^^^^^^^^^^^^^^^^^^
  File "<frozen importlib._bootstrap>", line 1387, in _gcd_import
  File "<frozen importlib._bootstrap>", line 1360, in _find_and_load
  File "<frozen importlib._bootstrap>", line 1331, in _find_and_load_unlocked
  File "<frozen importlib._bootstrap>", line 935, in _load_unlocked
  File "<frozen importlib._bootstrap_external>", line 995, in exec_module
  File "<frozen importlib._bootstrap>", line 488, in _call_with_frames_removed
  File "/mnt/c/Users/HAng3/Documents/wafer-defect-library/backend/app.py", line 5, in <module>
    from flask_cors import CORS
ModuleNotFoundError: No module named 'flask_cors'
[2025-04-09 09:41:27 +0800] [1676] [ERROR] Exception in worker process
Traceback (most recent call last):
  File "/mnt/c/Users/HAng3/Documents/wafer-defect-library/backend/venv/lib/python3.12/site-packages/gunicorn/arbiter.py", line 608, in spawn_worker
    worker.init_process()
  File "/mnt/c/Users/HAng3/Documents/wafer-defect-library/backend/venv/lib/python3.12/site-packages/gunicorn/workers/base.py", line 135, in init_process
    self.load_wsgi()
  File "/mnt/c/Users/HAng3/Documents/wafer-defect-library/backend/venv/lib/python3.12/site-packages/gunicorn/workers/base.py", line 147, in load_wsgi
    self.wsgi = self.app.wsgi()
                ^^^^^^^^^^^^^^^
  File "/mnt/c/Users/HAng3/Documents/wafer-defect-library/backend/venv/lib/python3.12/site-packages/gunicorn/app/base.py", line 66, in wsgi
    self.callable = self.load()
                    ^^^^^^^^^^^
  File "/mnt/c/Users/HAng3/Documents/wafer-defect-library/backend/venv/lib/python3.12/site-packages/gunicorn/app/wsgiapp.py", line 57, in load
    return self.load_wsgiapp()
           ^^^^^^^^^^^^^^^^^^^
  File "/mnt/c/Users/HAng3/Documents/wafer-defect-library/backend/venv/lib/python3.12/site-packages/gunicorn/app/wsgiapp.py", line 47, in load_wsgiapp
    return util.import_app(self.app_uri)
           ^^^^^^^^^^^^^^^^^^^^^^^^^^^^^
  File "/mnt/c/Users/HAng3/Documents/wafer-defect-library/backend/venv/lib/python3.12/site-packages/gunicorn/util.py", line 370, in import_app
    mod = importlib.import_module(module)
          ^^^^^^^^^^^^^^^^^^^^^^^^^^^^^^^
  File "/usr/lib/python3.12/importlib/__init__.py", line 90, in import_module
    return _bootstrap._gcd_import(name[level:], package, level)
           ^^^^^^^^^^^^^^^^^^^^^^^^^^^^^^^^^^^^^^^^^^^^^^^^^^^^
  File "<frozen importlib._bootstrap>", line 1387, in _gcd_import
  File "<frozen importlib._bootstrap>", line 1360, in _find_and_load
  File "<frozen importlib._bootstrap>", line 1331, in _find_and_load_unlocked
  File "<frozen importlib._bootstrap>", line 935, in _load_unlocked
  File "<frozen importlib._bootstrap_external>", line 995, in exec_module
  File "<frozen importlib._bootstrap>", line 488, in _call_with_frames_removed
  File "/mnt/c/Users/HAng3/Documents/wafer-defect-library/backend/app.py", line 5, in <module>
    from flask_cors import CORS
ModuleNotFoundError: No module named 'flask_cors'
[2025-04-09 09:41:27 +0800] [1673] [ERROR] Exception in worker process
Traceback (most recent call last):
  File "/mnt/c/Users/HAng3/Documents/wafer-defect-library/backend/venv/lib/python3.12/site-packages/gunicorn/arbiter.py", line 608, in spawn_worker
    worker.init_process()
  File "/mnt/c/Users/HAng3/Documents/wafer-defect-library/backend/venv/lib/python3.12/site-packages/gunicorn/workers/base.py", line 135, in init_process
    self.load_wsgi()
  File "/mnt/c/Users/HAng3/Documents/wafer-defect-library/backend/venv/lib/python3.12/site-packages/gunicorn/workers/base.py", line 147, in load_wsgi
    self.wsgi = self.app.wsgi()
                ^^^^^^^^^^^^^^^
  File "/mnt/c/Users/HAng3/Documents/wafer-defect-library/backend/venv/lib/python3.12/site-packages/gunicorn/app/base.py", line 66, in wsgi
    self.callable = self.load()
                    ^^^^^^^^^^^
  File "/mnt/c/Users/HAng3/Documents/wafer-defect-library/backend/venv/lib/python3.12/site-packages/gunicorn/app/wsgiapp.py", line 57, in load
    return self.load_wsgiapp()
           ^^^^^^^^^^^^^^^^^^^
  File "/mnt/c/Users/HAng3/Documents/wafer-defect-library/backend/venv/lib/python3.12/site-packages/gunicorn/app/wsgiapp.py", line 47, in load_wsgiapp
    return util.import_app(self.app_uri)
           ^^^^^^^^^^^^^^^^^^^^^^^^^^^^^
  File "/mnt/c/Users/HAng3/Documents/wafer-defect-library/backend/venv/lib/python3.12/site-packages/gunicorn/util.py", line 370, in import_app
    mod = importlib.import_module(module)
          ^^^^^^^^^^^^^^^^^^^^^^^^^^^^^^^
  File "/usr/lib/python3.12/importlib/__init__.py", line 90, in import_module
    return _bootstrap._gcd_import(name[level:], package, level)
           ^^^^^^^^^^^^^^^^^^^^^^^^^^^^^^^^^^^^^^^^^^^^^^^^^^^^
  File "<frozen importlib._bootstrap>", line 1387, in _gcd_import
  File "<frozen importlib._bootstrap>", line 1360, in _find_and_load
  File "<frozen importlib._bootstrap>", line 1331, in _find_and_load_unlocked
  File "<frozen importlib._bootstrap>", line 935, in _load_unlocked
  File "<frozen importlib._bootstrap_external>", line 995, in exec_module
  File "<frozen importlib._bootstrap>", line 488, in _call_with_frames_removed
  File "/mnt/c/Users/HAng3/Documents/wafer-defect-library/backend/app.py", line 5, in <module>
    from flask_cors import CORS
ModuleNotFoundError: No module named 'flask_cors'
[2025-04-09 09:41:27 +0800] [1675] [ERROR] Exception in worker process
Traceback (most recent call last):
  File "/mnt/c/Users/HAng3/Documents/wafer-defect-library/backend/venv/lib/python3.12/site-packages/gunicorn/arbiter.py", line 608, in spawn_worker
    worker.init_process()
  File "/mnt/c/Users/HAng3/Documents/wafer-defect-library/backend/venv/lib/python3.12/site-packages/gunicorn/workers/base.py", line 135, in init_process
    self.load_wsgi()
  File "/mnt/c/Users/HAng3/Documents/wafer-defect-library/backend/venv/lib/python3.12/site-packages/gunicorn/workers/base.py", line 147, in load_wsgi
    self.wsgi = self.app.wsgi()
                ^^^^^^^^^^^^^^^
  File "/mnt/c/Users/HAng3/Documents/wafer-defect-library/backend/venv/lib/python3.12/site-packages/gunicorn/app/base.py", line 66, in wsgi
    self.callable = self.load()
                    ^^^^^^^^^^^
  File "/mnt/c/Users/HAng3/Documents/wafer-defect-library/backend/venv/lib/python3.12/site-packages/gunicorn/app/wsgiapp.py", line 57, in load
    return self.load_wsgiapp()
           ^^^^^^^^^^^^^^^^^^^
  File "/mnt/c/Users/HAng3/Documents/wafer-defect-library/backend/venv/lib/python3.12/site-packages/gunicorn/app/wsgiapp.py", line 47, in load_wsgiapp
    return util.import_app(self.app_uri)
           ^^^^^^^^^^^^^^^^^^^^^^^^^^^^^
  File "/mnt/c/Users/HAng3/Documents/wafer-defect-library/backend/venv/lib/python3.12/site-packages/gunicorn/util.py", line 370, in import_app
    mod = importlib.import_module(module)
          ^^^^^^^^^^^^^^^^^^^^^^^^^^^^^^^
  File "/usr/lib/python3.12/importlib/__init__.py", line 90, in import_module
    return _bootstrap._gcd_import(name[level:], package, level)
           ^^^^^^^^^^^^^^^^^^^^^^^^^^^^^^^^^^^^^^^^^^^^^^^^^^^^
  File "<frozen importlib._bootstrap>", line 1387, in _gcd_import
  File "<frozen importlib._bootstrap>", line 1360, in _find_and_load
  File "<frozen importlib._bootstrap>", line 1331, in _find_and_load_unlocked
  File "<frozen importlib._bootstrap>", line 935, in _load_unlocked
  File "<frozen importlib._bootstrap_external>", line 995, in exec_module
  File "<frozen importlib._bootstrap>", line 488, in _call_with_frames_removed
  File "/mnt/c/Users/HAng3/Documents/wafer-defect-library/backend/app.py", line 5, in <module>
    from flask_cors import CORS
ModuleNotFoundError: No module named 'flask_cors'
[2025-04-09 09:41:27 +0800] [1682] [ERROR] Exception in worker process
Traceback (most recent call last):
  File "/mnt/c/Users/HAng3/Documents/wafer-defect-library/backend/venv/lib/python3.12/site-packages/gunicorn/arbiter.py", line 608, in spawn_worker
    worker.init_process()
  File "/mnt/c/Users/HAng3/Documents/wafer-defect-library/backend/venv/lib/python3.12/site-packages/gunicorn/workers/base.py", line 135, in init_process
    self.load_wsgi()
  File "/mnt/c/Users/HAng3/Documents/wafer-defect-library/backend/venv/lib/python3.12/site-packages/gunicorn/workers/base.py", line 147, in load_wsgi
    self.wsgi = self.app.wsgi()
                ^^^^^^^^^^^^^^^
  File "/mnt/c/Users/HAng3/Documents/wafer-defect-library/backend/venv/lib/python3.12/site-packages/gunicorn/app/base.py", line 66, in wsgi
    self.callable = self.load()
                    ^^^^^^^^^^^
  File "/mnt/c/Users/HAng3/Documents/wafer-defect-library/backend/venv/lib/python3.12/site-packages/gunicorn/app/wsgiapp.py", line 57, in load
    return self.load_wsgiapp()
           ^^^^^^^^^^^^^^^^^^^
  File "/mnt/c/Users/HAng3/Documents/wafer-defect-library/backend/venv/lib/python3.12/site-packages/gunicorn/app/wsgiapp.py", line 47, in load_wsgiapp
    return util.import_app(self.app_uri)
           ^^^^^^^^^^^^^^^^^^^^^^^^^^^^^
  File "/mnt/c/Users/HAng3/Documents/wafer-defect-library/backend/venv/lib/python3.12/site-packages/gunicorn/util.py", line 370, in import_app
    mod = importlib.import_module(module)
          ^^^^^^^^^^^^^^^^^^^^^^^^^^^^^^^
  File "/usr/lib/python3.12/importlib/__init__.py", line 90, in import_module
    return _bootstrap._gcd_import(name[level:], package, level)
           ^^^^^^^^^^^^^^^^^^^^^^^^^^^^^^^^^^^^^^^^^^^^^^^^^^^^
  File "<frozen importlib._bootstrap>", line 1387, in _gcd_import
  File "<frozen importlib._bootstrap>", line 1360, in _find_and_load
  File "<frozen importlib._bootstrap>", line 1331, in _find_and_load_unlocked
  File "<frozen importlib._bootstrap>", line 935, in _load_unlocked
  File "<frozen importlib._bootstrap_external>", line 995, in exec_module
  File "<frozen importlib._bootstrap>", line 488, in _call_with_frames_removed
  File "/mnt/c/Users/HAng3/Documents/wafer-defect-library/backend/app.py", line 5, in <module>
    from flask_cors import CORS
ModuleNotFoundError: No module named 'flask_cors'
[2025-04-09 09:41:27 +0800] [1674] [ERROR] Exception in worker process
Traceback (most recent call last):
  File "/mnt/c/Users/HAng3/Documents/wafer-defect-library/backend/venv/lib/python3.12/site-packages/gunicorn/arbiter.py", line 608, in spawn_worker
    worker.init_process()
  File "/mnt/c/Users/HAng3/Documents/wafer-defect-library/backend/venv/lib/python3.12/site-packages/gunicorn/workers/base.py", line 135, in init_process
    self.load_wsgi()
  File "/mnt/c/Users/HAng3/Documents/wafer-defect-library/backend/venv/lib/python3.12/site-packages/gunicorn/workers/base.py", line 147, in load_wsgi
    self.wsgi = self.app.wsgi()
                ^^^^^^^^^^^^^^^
  File "/mnt/c/Users/HAng3/Documents/wafer-defect-library/backend/venv/lib/python3.12/site-packages/gunicorn/app/base.py", line 66, in wsgi
    self.callable = self.load()
                    ^^^^^^^^^^^
  File "/mnt/c/Users/HAng3/Documents/wafer-defect-library/backend/venv/lib/python3.12/site-packages/gunicorn/app/wsgiapp.py", line 57, in load
    return self.load_wsgiapp()
           ^^^^^^^^^^^^^^^^^^^
  File "/mnt/c/Users/HAng3/Documents/wafer-defect-library/backend/venv/lib/python3.12/site-packages/gunicorn/app/wsgiapp.py", line 47, in load_wsgiapp
    return util.import_app(self.app_uri)
           ^^^^^^^^^^^^^^^^^^^^^^^^^^^^^
  File "/mnt/c/Users/HAng3/Documents/wafer-defect-library/backend/venv/lib/python3.12/site-packages/gunicorn/util.py", line 370, in import_app
    mod = importlib.import_module(module)
          ^^^^^^^^^^^^^^^^^^^^^^^^^^^^^^^
  File "/usr/lib/python3.12/importlib/__init__.py", line 90, in import_module
    return _bootstrap._gcd_import(name[level:], package, level)
           ^^^^^^^^^^^^^^^^^^^^^^^^^^^^^^^^^^^^^^^^^^^^^^^^^^^^
  File "<frozen importlib._bootstrap>", line 1387, in _gcd_import
  File "<frozen importlib._bootstrap>", line 1360, in _find_and_load
  File "<frozen importlib._bootstrap>", line 1331, in _find_and_load_unlocked
  File "<frozen importlib._bootstrap>", line 935, in _load_unlocked
  File "<frozen importlib._bootstrap_external>", line 995, in exec_module
  File "<frozen importlib._bootstrap>", line 488, in _call_with_frames_removed
  File "/mnt/c/Users/HAng3/Documents/wafer-defect-library/backend/app.py", line 5, in <module>
    from flask_cors import CORS
ModuleNotFoundError: No module named 'flask_cors'
[2025-04-09 09:41:27 +0800] [1677] [ERROR] Exception in worker process
Traceback (most recent call last):
  File "/mnt/c/Users/HAng3/Documents/wafer-defect-library/backend/venv/lib/python3.12/site-packages/gunicorn/arbiter.py", line 608, in spawn_worker
    worker.init_process()
  File "/mnt/c/Users/HAng3/Documents/wafer-defect-library/backend/venv/lib/python3.12/site-packages/gunicorn/workers/base.py", line 135, in init_process
    self.load_wsgi()
  File "/mnt/c/Users/HAng3/Documents/wafer-defect-library/backend/venv/lib/python3.12/site-packages/gunicorn/workers/base.py", line 147, in load_wsgi
    self.wsgi = self.app.wsgi()
                ^^^^^^^^^^^^^^^
  File "/mnt/c/Users/HAng3/Documents/wafer-defect-library/backend/venv/lib/python3.12/site-packages/gunicorn/app/base.py", line 66, in wsgi
    self.callable = self.load()
                    ^^^^^^^^^^^
  File "/mnt/c/Users/HAng3/Documents/wafer-defect-library/backend/venv/lib/python3.12/site-packages/gunicorn/app/wsgiapp.py", line 57, in load
    return self.load_wsgiapp()
           ^^^^^^^^^^^^^^^^^^^
  File "/mnt/c/Users/HAng3/Documents/wafer-defect-library/backend/venv/lib/python3.12/site-packages/gunicorn/app/wsgiapp.py", line 47, in load_wsgiapp
    return util.import_app(self.app_uri)
           ^^^^^^^^^^^^^^^^^^^^^^^^^^^^^
  File "/mnt/c/Users/HAng3/Documents/wafer-defect-library/backend/venv/lib/python3.12/site-packages/gunicorn/util.py", line 370, in import_app
    mod = importlib.import_module(module)
          ^^^^^^^^^^^^^^^^^^^^^^^^^^^^^^^
  File "/usr/lib/python3.12/importlib/__init__.py", line 90, in import_module
    return _bootstrap._gcd_import(name[level:], package, level)
           ^^^^^^^^^^^^^^^^^^^^^^^^^^^^^^^^^^^^^^^^^^^^^^^^^^^^
  File "<frozen importlib._bootstrap>", line 1387, in _gcd_import
  File "<frozen importlib._bootstrap>", line 1360, in _find_and_load
  File "<frozen importlib._bootstrap>", line 1331, in _find_and_load_unlocked
  File "<frozen importlib._bootstrap>", line 935, in _load_unlocked
  File "<frozen importlib._bootstrap_external>", line 995, in exec_module
  File "<frozen importlib._bootstrap>", line 488, in _call_with_frames_removed
  File "/mnt/c/Users/HAng3/Documents/wafer-defect-library/backend/app.py", line 5, in <module>
    from flask_cors import CORS
ModuleNotFoundError: No module named 'flask_cors'
[2025-04-09 09:41:28 +0800] [1689] [INFO] Worker exiting (pid: 1689)
[2025-04-09 09:41:27 +0800] [1684] [ERROR] Exception in worker process
Traceback (most recent call last):
  File "/mnt/c/Users/HAng3/Documents/wafer-defect-library/backend/venv/lib/python3.12/site-packages/gunicorn/arbiter.py", line 608, in spawn_worker
    worker.init_process()
  File "/mnt/c/Users/HAng3/Documents/wafer-defect-library/backend/venv/lib/python3.12/site-packages/gunicorn/workers/base.py", line 135, in init_process
    self.load_wsgi()
  File "/mnt/c/Users/HAng3/Documents/wafer-defect-library/backend/venv/lib/python3.12/site-packages/gunicorn/workers/base.py", line 147, in load_wsgi
    self.wsgi = self.app.wsgi()
                ^^^^^^^^^^^^^^^
  File "/mnt/c/Users/HAng3/Documents/wafer-defect-library/backend/venv/lib/python3.12/site-packages/gunicorn/app/base.py", line 66, in wsgi
    self.callable = self.load()
                    ^^^^^^^^^^^
  File "/mnt/c/Users/HAng3/Documents/wafer-defect-library/backend/venv/lib/python3.12/site-packages/gunicorn/app/wsgiapp.py", line 57, in load
    return self.load_wsgiapp()
           ^^^^^^^^^^^^^^^^^^^
  File "/mnt/c/Users/HAng3/Documents/wafer-defect-library/backend/venv/lib/python3.12/site-packages/gunicorn/app/wsgiapp.py", line 47, in load_wsgiapp
    return util.import_app(self.app_uri)
           ^^^^^^^^^^^^^^^^^^^^^^^^^^^^^
  File "/mnt/c/Users/HAng3/Documents/wafer-defect-library/backend/venv/lib/python3.12/site-packages/gunicorn/util.py", line 370, in import_app
    mod = importlib.import_module(module)
          ^^^^^^^^^^^^^^^^^^^^^^^^^^^^^^^
  File "/usr/lib/python3.12/importlib/__init__.py", line 90, in import_module
    return _bootstrap._gcd_import(name[level:], package, level)
           ^^^^^^^^^^^^^^^^^^^^^^^^^^^^^^^^^^^^^^^^^^^^^^^^^^^^
  File "<frozen importlib._bootstrap>", line 1387, in _gcd_import
  File "<frozen importlib._bootstrap>", line 1360, in _find_and_load
  File "<frozen importlib._bootstrap>", line 1331, in _find_and_load_unlocked
  File "<frozen importlib._bootstrap>", line 935, in _load_unlocked
  File "<frozen importlib._bootstrap_external>", line 995, in exec_module
  File "<frozen importlib._bootstrap>", line 488, in _call_with_frames_removed
  File "/mnt/c/Users/HAng3/Documents/wafer-defect-library/backend/app.py", line 5, in <module>
    from flask_cors import CORS
ModuleNotFoundError: No module named 'flask_cors'
[2025-04-09 09:41:28 +0800] [1685] [INFO] Worker exiting (pid: 1685)
[2025-04-09 09:41:27 +0800] [1688] [ERROR] Exception in worker process
Traceback (most recent call last):
  File "/mnt/c/Users/HAng3/Documents/wafer-defect-library/backend/venv/lib/python3.12/site-packages/gunicorn/arbiter.py", line 608, in spawn_worker
    worker.init_process()
  File "/mnt/c/Users/HAng3/Documents/wafer-defect-library/backend/venv/lib/python3.12/site-packages/gunicorn/workers/base.py", line 135, in init_process
    self.load_wsgi()
  File "/mnt/c/Users/HAng3/Documents/wafer-defect-library/backend/venv/lib/python3.12/site-packages/gunicorn/workers/base.py", line 147, in load_wsgi
    self.wsgi = self.app.wsgi()
                ^^^^^^^^^^^^^^^
  File "/mnt/c/Users/HAng3/Documents/wafer-defect-library/backend/venv/lib/python3.12/site-packages/gunicorn/app/base.py", line 66, in wsgi
    self.callable = self.load()
                    ^^^^^^^^^^^
  File "/mnt/c/Users/HAng3/Documents/wafer-defect-library/backend/venv/lib/python3.12/site-packages/gunicorn/app/wsgiapp.py", line 57, in load
    return self.load_wsgiapp()
           ^^^^^^^^^^^^^^^^^^^
  File "/mnt/c/Users/HAng3/Documents/wafer-defect-library/backend/venv/lib/python3.12/site-packages/gunicorn/app/wsgiapp.py", line 47, in load_wsgiapp
    return util.import_app(self.app_uri)
           ^^^^^^^^^^^^^^^^^^^^^^^^^^^^^
  File "/mnt/c/Users/HAng3/Documents/wafer-defect-library/backend/venv/lib/python3.12/site-packages/gunicorn/util.py", line 370, in import_app
    mod = importlib.import_module(module)
          ^^^^^^^^^^^^^^^^^^^^^^^^^^^^^^^
  File "/usr/lib/python3.12/importlib/__init__.py", line 90, in import_module
    return _bootstrap._gcd_import(name[level:], package, level)
           ^^^^^^^^^^^^^^^^^^^^^^^^^^^^^^^^^^^^^^^^^^^^^^^^^^^^
  File "<frozen importlib._bootstrap>", line 1387, in _gcd_import
  File "<frozen importlib._bootstrap>", line 1360, in _find_and_load
  File "<frozen importlib._bootstrap>", line 1331, in _find_and_load_unlocked
  File "<frozen importlib._bootstrap>", line 935, in _load_unlocked
  File "<frozen importlib._bootstrap_external>", line 995, in exec_module
  File "<frozen importlib._bootstrap>", line 488, in _call_with_frames_removed
  File "/mnt/c/Users/HAng3/Documents/wafer-defect-library/backend/app.py", line 5, in <module>
    from flask_cors import CORS
ModuleNotFoundError: No module named 'flask_cors'
[2025-04-09 09:41:28 +0800] [1683] [INFO] Worker exiting (pid: 1683)
[2025-04-09 09:41:28 +0800] [1681] [INFO] Worker exiting (pid: 1681)
[2025-04-09 09:41:27 +0800] [1687] [ERROR] Exception in worker process
Traceback (most recent call last):
  File "/mnt/c/Users/HAng3/Documents/wafer-defect-library/backend/venv/lib/python3.12/site-packages/gunicorn/arbiter.py", line 608, in spawn_worker
    worker.init_process()
  File "/mnt/c/Users/HAng3/Documents/wafer-defect-library/backend/venv/lib/python3.12/site-packages/gunicorn/workers/base.py", line 135, in init_process
    self.load_wsgi()
  File "/mnt/c/Users/HAng3/Documents/wafer-defect-library/backend/venv/lib/python3.12/site-packages/gunicorn/workers/base.py", line 147, in load_wsgi
    self.wsgi = self.app.wsgi()
                ^^^^^^^^^^^^^^^
  File "/mnt/c/Users/HAng3/Documents/wafer-defect-library/backend/venv/lib/python3.12/site-packages/gunicorn/app/base.py", line 66, in wsgi
    self.callable = self.load()
                    ^^^^^^^^^^^
  File "/mnt/c/Users/HAng3/Documents/wafer-defect-library/backend/venv/lib/python3.12/site-packages/gunicorn/app/wsgiapp.py", line 57, in load
    return self.load_wsgiapp()
           ^^^^^^^^^^^^^^^^^^^
  File "/mnt/c/Users/HAng3/Documents/wafer-defect-library/backend/venv/lib/python3.12/site-packages/gunicorn/app/wsgiapp.py", line 47, in load_wsgiapp
    return util.import_app(self.app_uri)
           ^^^^^^^^^^^^^^^^^^^^^^^^^^^^^
  File "/mnt/c/Users/HAng3/Documents/wafer-defect-library/backend/venv/lib/python3.12/site-packages/gunicorn/util.py", line 370, in import_app
    mod = importlib.import_module(module)
          ^^^^^^^^^^^^^^^^^^^^^^^^^^^^^^^
  File "/usr/lib/python3.12/importlib/__init__.py", line 90, in import_module
    return _bootstrap._gcd_import(name[level:], package, level)
           ^^^^^^^^^^^^^^^^^^^^^^^^^^^^^^^^^^^^^^^^^^^^^^^^^^^^
  File "<frozen importlib._bootstrap>", line 1387, in _gcd_import
  File "<frozen importlib._bootstrap>", line 1360, in _find_and_load
  File "<frozen importlib._bootstrap>", line 1331, in _find_and_load_unlocked
  File "<frozen importlib._bootstrap>", line 935, in _load_unlocked
  File "<frozen importlib._bootstrap_external>", line 995, in exec_module
  File "<frozen importlib._bootstrap>", line 488, in _call_with_frames_removed
  File "/mnt/c/Users/HAng3/Documents/wafer-defect-library/backend/app.py", line 5, in <module>
    from flask_cors import CORS
ModuleNotFoundError: No module named 'flask_cors'
[2025-04-09 09:41:28 +0800] [1680] [INFO] Worker exiting (pid: 1680)
[2025-04-09 09:41:28 +0800] [1686] [INFO] Worker exiting (pid: 1686)
[2025-04-09 09:41:28 +0800] [1676] [INFO] Worker exiting (pid: 1676)
[2025-04-09 09:41:28 +0800] [1678] [INFO] Worker exiting (pid: 1678)
[2025-04-09 09:41:28 +0800] [1673] [INFO] Worker exiting (pid: 1673)
[2025-04-09 09:41:28 +0800] [1675] [INFO] Worker exiting (pid: 1675)
[2025-04-09 09:41:28 +0800] [1682] [INFO] Worker exiting (pid: 1682)
[2025-04-09 09:41:28 +0800] [1674] [INFO] Worker exiting (pid: 1674)
[2025-04-09 09:41:28 +0800] [1677] [INFO] Worker exiting (pid: 1677)
[2025-04-09 09:41:28 +0800] [1684] [INFO] Worker exiting (pid: 1684)
[2025-04-09 09:41:28 +0800] [1688] [INFO] Worker exiting (pid: 1688)
[2025-04-09 09:41:28 +0800] [1687] [INFO] Worker exiting (pid: 1687)
[2025-04-09 09:41:28 +0800] [1672] [ERROR] Worker (pid:1685) exited with code 3
[2025-04-09 09:41:28 +0800] [1672] [ERROR] Worker (pid:1679) exited with code 3
[2025-04-09 09:41:28 +0800] [1672] [ERROR] Worker (pid:1673) was sent SIGTERM!
[2025-04-09 09:41:29 +0800] [1672] [ERROR] Worker (pid:1675) was sent SIGTERM!
[2025-04-09 09:41:29 +0800] [1672] [ERROR] Worker (pid:1677) was sent SIGTERM!
[2025-04-09 09:41:29 +0800] [1672] [ERROR] Worker (pid:1676) was sent SIGTERM!
